 09/04/2025 10:21:24 AM - INFO - BOT TELEGRAM YOUTUBE

 09/04/2025 10:21:24 AM - INFO - bot chamado
 09/04/2025 10:22:13 AM - INFO - usuario esta tentando fazer download
 09/04/2025 10:22:15 AM - INFO - FIZ_UM_MALWARE: https://youtu.be/4pobgFPm19c?si=_rY-xtWbi0HXw-hD
 09/04/2025 10:22:19 AM - INFO - o usuario pediu a opcao video
 09/04/2025 10:23:03 AM - INFO - caminho: C:\Users\paulo.welton\Desktop\bot_telegram_youtube\video\FIZ_UM_MALWARE.m4a
 09/04/2025 10:23:18 AM - INFO - ('Connection aborted.', timeout('The write operation timed out'))
 09/04/2025 10:39:39 AM - INFO - BOT TELEGRAM YOUTUBE

 09/04/2025 10:39:39 AM - INFO - bot chamado
 09/04/2025 10:39:57 AM - INFO - usuario esta tentando fazer download
 09/04/2025 10:39:59 AM - INFO - FIZ_UM_MALWARE: https://youtu.be/4pobgFPm19c?si=_rY-xtWbi0HXw-hD
 09/04/2025 10:40:01 AM - INFO - o usuario pediu a opcao video
 09/04/2025 10:40:51 AM - INFO - caminho: C:\Users\paulo.welton\Desktop\bot_telegram_youtube\video\FIZ_UM_MALWARE.m4a
 09/04/2025 10:41:20 AM - INFO - ('Connection aborted.', ConnectionResetError(10054, 'Foi forçado o cancelamento de uma conexão existente pelo host remoto', None, 10054, None))
 09/04/2025 10:45:27 AM - ERROR - Threaded polling exception: A request to the Telegram API was unsuccessful. Error code: 409. Description: Conflict: terminated by setWebhook request
 09/04/2025 10:45:27 AM - ERROR - Exception traceback:
Traceback (most recent call last):
  File "C:\Users\paulo.welton\AppData\Local\Programs\Python\Python39\lib\site-packages\telebot\__init__.py", line 1073, in __threaded_polling
    polling_thread.raise_exceptions()
  File "C:\Users\paulo.welton\AppData\Local\Programs\Python\Python39\lib\site-packages\telebot\util.py", line 109, in raise_exceptions
    raise self.exception_info
  File "C:\Users\paulo.welton\AppData\Local\Programs\Python\Python39\lib\site-packages\telebot\util.py", line 91, in run
    task(*args, **kwargs)
  File "C:\Users\paulo.welton\AppData\Local\Programs\Python\Python39\lib\site-packages\telebot\__init__.py", line 649, in __retrieve_updates
    updates = self.get_updates(offset=(self.last_update_id + 1),
  File "C:\Users\paulo.welton\AppData\Local\Programs\Python\Python39\lib\site-packages\telebot\__init__.py", line 623, in get_updates
    json_updates = apihelper.get_updates(self.token, offset, limit, timeout, allowed_updates, long_polling_timeout)
  File "C:\Users\paulo.welton\AppData\Local\Programs\Python\Python39\lib\site-packages\telebot\apihelper.py", line 321, in get_updates
    return _make_request(token, method_url, params=payload)
  File "C:\Users\paulo.welton\AppData\Local\Programs\Python\Python39\lib\site-packages\telebot\apihelper.py", line 162, in _make_request
    json_result = _check_result(method_name, result)
  File "C:\Users\paulo.welton\AppData\Local\Programs\Python\Python39\lib\site-packages\telebot\apihelper.py", line 189, in _check_result
    raise ApiTelegramException(method_name, result, result_json)
telebot.apihelper.ApiTelegramException: A request to the Telegram API was unsuccessful. Error code: 409. Description: Conflict: terminated by setWebhook request

 09/04/2025 10:45:30 AM - ERROR - Threaded polling exception: A request to the Telegram API was unsuccessful. Error code: 409. Description: Conflict: can't use getUpdates method while webhook is active; use deleteWebhook to delete the webhook first
 09/04/2025 10:45:30 AM - ERROR - Exception traceback:
Traceback (most recent call last):
  File "C:\Users\paulo.welton\AppData\Local\Programs\Python\Python39\lib\site-packages\telebot\__init__.py", line 1073, in __threaded_polling
    polling_thread.raise_exceptions()
  File "C:\Users\paulo.welton\AppData\Local\Programs\Python\Python39\lib\site-packages\telebot\util.py", line 109, in raise_exceptions
    raise self.exception_info
  File "C:\Users\paulo.welton\AppData\Local\Programs\Python\Python39\lib\site-packages\telebot\util.py", line 91, in run
    task(*args, **kwargs)
  File "C:\Users\paulo.welton\AppData\Local\Programs\Python\Python39\lib\site-packages\telebot\__init__.py", line 649, in __retrieve_updates
    updates = self.get_updates(offset=(self.last_update_id + 1),
  File "C:\Users\paulo.welton\AppData\Local\Programs\Python\Python39\lib\site-packages\telebot\__init__.py", line 623, in get_updates
    json_updates = apihelper.get_updates(self.token, offset, limit, timeout, allowed_updates, long_polling_timeout)
  File "C:\Users\paulo.welton\AppData\Local\Programs\Python\Python39\lib\site-packages\telebot\apihelper.py", line 321, in get_updates
    return _make_request(token, method_url, params=payload)
  File "C:\Users\paulo.welton\AppData\Local\Programs\Python\Python39\lib\site-packages\telebot\apihelper.py", line 162, in _make_request
    json_result = _check_result(method_name, result)
  File "C:\Users\paulo.welton\AppData\Local\Programs\Python\Python39\lib\site-packages\telebot\apihelper.py", line 189, in _check_result
    raise ApiTelegramException(method_name, result, result_json)
telebot.apihelper.ApiTelegramException: A request to the Telegram API was unsuccessful. Error code: 409. Description: Conflict: can't use getUpdates method while webhook is active; use deleteWebhook to delete the webhook first

 09/04/2025 10:45:31 AM - ERROR - Threaded polling exception: A request to the Telegram API was unsuccessful. Error code: 409. Description: Conflict: can't use getUpdates method while webhook is active; use deleteWebhook to delete the webhook first
 09/04/2025 10:45:31 AM - ERROR - Exception traceback:
Traceback (most recent call last):
  File "C:\Users\paulo.welton\AppData\Local\Programs\Python\Python39\lib\site-packages\telebot\__init__.py", line 1073, in __threaded_polling
    polling_thread.raise_exceptions()
  File "C:\Users\paulo.welton\AppData\Local\Programs\Python\Python39\lib\site-packages\telebot\util.py", line 109, in raise_exceptions
    raise self.exception_info
  File "C:\Users\paulo.welton\AppData\Local\Programs\Python\Python39\lib\site-packages\telebot\util.py", line 91, in run
    task(*args, **kwargs)
  File "C:\Users\paulo.welton\AppData\Local\Programs\Python\Python39\lib\site-packages\telebot\__init__.py", line 649, in __retrieve_updates
    updates = self.get_updates(offset=(self.last_update_id + 1),
  File "C:\Users\paulo.welton\AppData\Local\Programs\Python\Python39\lib\site-packages\telebot\__init__.py", line 623, in get_updates
    json_updates = apihelper.get_updates(self.token, offset, limit, timeout, allowed_updates, long_polling_timeout)
  File "C:\Users\paulo.welton\AppData\Local\Programs\Python\Python39\lib\site-packages\telebot\apihelper.py", line 321, in get_updates
    return _make_request(token, method_url, params=payload)
  File "C:\Users\paulo.welton\AppData\Local\Programs\Python\Python39\lib\site-packages\telebot\apihelper.py", line 162, in _make_request
    json_result = _check_result(method_name, result)
  File "C:\Users\paulo.welton\AppData\Local\Programs\Python\Python39\lib\site-packages\telebot\apihelper.py", line 189, in _check_result
    raise ApiTelegramException(method_name, result, result_json)
telebot.apihelper.ApiTelegramException: A request to the Telegram API was unsuccessful. Error code: 409. Description: Conflict: can't use getUpdates method while webhook is active; use deleteWebhook to delete the webhook first

 09/04/2025 10:45:35 AM - ERROR - Threaded polling exception: A request to the Telegram API was unsuccessful. Error code: 409. Description: Conflict: can't use getUpdates method while webhook is active; use deleteWebhook to delete the webhook first
 09/04/2025 10:45:35 AM - ERROR - Exception traceback:
Traceback (most recent call last):
  File "C:\Users\paulo.welton\AppData\Local\Programs\Python\Python39\lib\site-packages\telebot\__init__.py", line 1073, in __threaded_polling
    polling_thread.raise_exceptions()
  File "C:\Users\paulo.welton\AppData\Local\Programs\Python\Python39\lib\site-packages\telebot\util.py", line 109, in raise_exceptions
    raise self.exception_info
  File "C:\Users\paulo.welton\AppData\Local\Programs\Python\Python39\lib\site-packages\telebot\util.py", line 91, in run
    task(*args, **kwargs)
  File "C:\Users\paulo.welton\AppData\Local\Programs\Python\Python39\lib\site-packages\telebot\__init__.py", line 649, in __retrieve_updates
    updates = self.get_updates(offset=(self.last_update_id + 1),
  File "C:\Users\paulo.welton\AppData\Local\Programs\Python\Python39\lib\site-packages\telebot\__init__.py", line 623, in get_updates
    json_updates = apihelper.get_updates(self.token, offset, limit, timeout, allowed_updates, long_polling_timeout)
  File "C:\Users\paulo.welton\AppData\Local\Programs\Python\Python39\lib\site-packages\telebot\apihelper.py", line 321, in get_updates
    return _make_request(token, method_url, params=payload)
  File "C:\Users\paulo.welton\AppData\Local\Programs\Python\Python39\lib\site-packages\telebot\apihelper.py", line 162, in _make_request
    json_result = _check_result(method_name, result)
  File "C:\Users\paulo.welton\AppData\Local\Programs\Python\Python39\lib\site-packages\telebot\apihelper.py", line 189, in _check_result
    raise ApiTelegramException(method_name, result, result_json)
telebot.apihelper.ApiTelegramException: A request to the Telegram API was unsuccessful. Error code: 409. Description: Conflict: can't use getUpdates method while webhook is active; use deleteWebhook to delete the webhook first

 09/04/2025 10:45:37 AM - ERROR - Threaded polling exception: A request to the Telegram API was unsuccessful. Error code: 409. Description: Conflict: can't use getUpdates method while webhook is active; use deleteWebhook to delete the webhook first
 09/04/2025 10:45:37 AM - ERROR - Exception traceback:
Traceback (most recent call last):
  File "C:\Users\paulo.welton\AppData\Local\Programs\Python\Python39\lib\site-packages\telebot\__init__.py", line 1073, in __threaded_polling
    polling_thread.raise_exceptions()
  File "C:\Users\paulo.welton\AppData\Local\Programs\Python\Python39\lib\site-packages\telebot\util.py", line 109, in raise_exceptions
    raise self.exception_info
  File "C:\Users\paulo.welton\AppData\Local\Programs\Python\Python39\lib\site-packages\telebot\util.py", line 91, in run
    task(*args, **kwargs)
  File "C:\Users\paulo.welton\AppData\Local\Programs\Python\Python39\lib\site-packages\telebot\__init__.py", line 649, in __retrieve_updates
    updates = self.get_updates(offset=(self.last_update_id + 1),
  File "C:\Users\paulo.welton\AppData\Local\Programs\Python\Python39\lib\site-packages\telebot\__init__.py", line 623, in get_updates
    json_updates = apihelper.get_updates(self.token, offset, limit, timeout, allowed_updates, long_polling_timeout)
  File "C:\Users\paulo.welton\AppData\Local\Programs\Python\Python39\lib\site-packages\telebot\apihelper.py", line 321, in get_updates
    return _make_request(token, method_url, params=payload)
  File "C:\Users\paulo.welton\AppData\Local\Programs\Python\Python39\lib\site-packages\telebot\apihelper.py", line 162, in _make_request
    json_result = _check_result(method_name, result)
  File "C:\Users\paulo.welton\AppData\Local\Programs\Python\Python39\lib\site-packages\telebot\apihelper.py", line 189, in _check_result
    raise ApiTelegramException(method_name, result, result_json)
telebot.apihelper.ApiTelegramException: A request to the Telegram API was unsuccessful. Error code: 409. Description: Conflict: can't use getUpdates method while webhook is active; use deleteWebhook to delete the webhook first

 09/04/2025 10:45:41 AM - ERROR - Threaded polling exception: A request to the Telegram API was unsuccessful. Error code: 409. Description: Conflict: can't use getUpdates method while webhook is active; use deleteWebhook to delete the webhook first
 09/04/2025 10:45:41 AM - ERROR - Exception traceback:
Traceback (most recent call last):
  File "C:\Users\paulo.welton\AppData\Local\Programs\Python\Python39\lib\site-packages\telebot\__init__.py", line 1073, in __threaded_polling
    polling_thread.raise_exceptions()
  File "C:\Users\paulo.welton\AppData\Local\Programs\Python\Python39\lib\site-packages\telebot\util.py", line 109, in raise_exceptions
    raise self.exception_info
  File "C:\Users\paulo.welton\AppData\Local\Programs\Python\Python39\lib\site-packages\telebot\util.py", line 91, in run
    task(*args, **kwargs)
  File "C:\Users\paulo.welton\AppData\Local\Programs\Python\Python39\lib\site-packages\telebot\__init__.py", line 649, in __retrieve_updates
    updates = self.get_updates(offset=(self.last_update_id + 1),
  File "C:\Users\paulo.welton\AppData\Local\Programs\Python\Python39\lib\site-packages\telebot\__init__.py", line 623, in get_updates
    json_updates = apihelper.get_updates(self.token, offset, limit, timeout, allowed_updates, long_polling_timeout)
  File "C:\Users\paulo.welton\AppData\Local\Programs\Python\Python39\lib\site-packages\telebot\apihelper.py", line 321, in get_updates
    return _make_request(token, method_url, params=payload)
  File "C:\Users\paulo.welton\AppData\Local\Programs\Python\Python39\lib\site-packages\telebot\apihelper.py", line 162, in _make_request
    json_result = _check_result(method_name, result)
  File "C:\Users\paulo.welton\AppData\Local\Programs\Python\Python39\lib\site-packages\telebot\apihelper.py", line 189, in _check_result
    raise ApiTelegramException(method_name, result, result_json)
telebot.apihelper.ApiTelegramException: A request to the Telegram API was unsuccessful. Error code: 409. Description: Conflict: can't use getUpdates method while webhook is active; use deleteWebhook to delete the webhook first

 09/04/2025 10:45:49 AM - ERROR - Threaded polling exception: A request to the Telegram API was unsuccessful. Error code: 409. Description: Conflict: can't use getUpdates method while webhook is active; use deleteWebhook to delete the webhook first
 09/04/2025 10:45:49 AM - ERROR - Exception traceback:
Traceback (most recent call last):
  File "C:\Users\paulo.welton\AppData\Local\Programs\Python\Python39\lib\site-packages\telebot\__init__.py", line 1073, in __threaded_polling
    polling_thread.raise_exceptions()
  File "C:\Users\paulo.welton\AppData\Local\Programs\Python\Python39\lib\site-packages\telebot\util.py", line 109, in raise_exceptions
    raise self.exception_info
  File "C:\Users\paulo.welton\AppData\Local\Programs\Python\Python39\lib\site-packages\telebot\util.py", line 91, in run
    task(*args, **kwargs)
  File "C:\Users\paulo.welton\AppData\Local\Programs\Python\Python39\lib\site-packages\telebot\__init__.py", line 649, in __retrieve_updates
    updates = self.get_updates(offset=(self.last_update_id + 1),
  File "C:\Users\paulo.welton\AppData\Local\Programs\Python\Python39\lib\site-packages\telebot\__init__.py", line 623, in get_updates
    json_updates = apihelper.get_updates(self.token, offset, limit, timeout, allowed_updates, long_polling_timeout)
  File "C:\Users\paulo.welton\AppData\Local\Programs\Python\Python39\lib\site-packages\telebot\apihelper.py", line 321, in get_updates
    return _make_request(token, method_url, params=payload)
  File "C:\Users\paulo.welton\AppData\Local\Programs\Python\Python39\lib\site-packages\telebot\apihelper.py", line 162, in _make_request
    json_result = _check_result(method_name, result)
  File "C:\Users\paulo.welton\AppData\Local\Programs\Python\Python39\lib\site-packages\telebot\apihelper.py", line 189, in _check_result
    raise ApiTelegramException(method_name, result, result_json)
telebot.apihelper.ApiTelegramException: A request to the Telegram API was unsuccessful. Error code: 409. Description: Conflict: can't use getUpdates method while webhook is active; use deleteWebhook to delete the webhook first

 09/04/2025 10:46:05 AM - ERROR - Threaded polling exception: A request to the Telegram API was unsuccessful. Error code: 409. Description: Conflict: can't use getUpdates method while webhook is active; use deleteWebhook to delete the webhook first
 09/04/2025 10:46:05 AM - ERROR - Exception traceback:
Traceback (most recent call last):
  File "C:\Users\paulo.welton\AppData\Local\Programs\Python\Python39\lib\site-packages\telebot\__init__.py", line 1073, in __threaded_polling
    polling_thread.raise_exceptions()
  File "C:\Users\paulo.welton\AppData\Local\Programs\Python\Python39\lib\site-packages\telebot\util.py", line 109, in raise_exceptions
    raise self.exception_info
  File "C:\Users\paulo.welton\AppData\Local\Programs\Python\Python39\lib\site-packages\telebot\util.py", line 91, in run
    task(*args, **kwargs)
  File "C:\Users\paulo.welton\AppData\Local\Programs\Python\Python39\lib\site-packages\telebot\__init__.py", line 649, in __retrieve_updates
    updates = self.get_updates(offset=(self.last_update_id + 1),
  File "C:\Users\paulo.welton\AppData\Local\Programs\Python\Python39\lib\site-packages\telebot\__init__.py", line 623, in get_updates
    json_updates = apihelper.get_updates(self.token, offset, limit, timeout, allowed_updates, long_polling_timeout)
  File "C:\Users\paulo.welton\AppData\Local\Programs\Python\Python39\lib\site-packages\telebot\apihelper.py", line 321, in get_updates
    return _make_request(token, method_url, params=payload)
  File "C:\Users\paulo.welton\AppData\Local\Programs\Python\Python39\lib\site-packages\telebot\apihelper.py", line 162, in _make_request
    json_result = _check_result(method_name, result)
  File "C:\Users\paulo.welton\AppData\Local\Programs\Python\Python39\lib\site-packages\telebot\apihelper.py", line 189, in _check_result
    raise ApiTelegramException(method_name, result, result_json)
telebot.apihelper.ApiTelegramException: A request to the Telegram API was unsuccessful. Error code: 409. Description: Conflict: can't use getUpdates method while webhook is active; use deleteWebhook to delete the webhook first

 09/04/2025 10:46:38 AM - ERROR - Threaded polling exception: A request to the Telegram API was unsuccessful. Error code: 409. Description: Conflict: can't use getUpdates method while webhook is active; use deleteWebhook to delete the webhook first
 09/04/2025 10:46:38 AM - ERROR - Exception traceback:
Traceback (most recent call last):
  File "C:\Users\paulo.welton\AppData\Local\Programs\Python\Python39\lib\site-packages\telebot\__init__.py", line 1073, in __threaded_polling
    polling_thread.raise_exceptions()
  File "C:\Users\paulo.welton\AppData\Local\Programs\Python\Python39\lib\site-packages\telebot\util.py", line 109, in raise_exceptions
    raise self.exception_info
  File "C:\Users\paulo.welton\AppData\Local\Programs\Python\Python39\lib\site-packages\telebot\util.py", line 91, in run
    task(*args, **kwargs)
  File "C:\Users\paulo.welton\AppData\Local\Programs\Python\Python39\lib\site-packages\telebot\__init__.py", line 649, in __retrieve_updates
    updates = self.get_updates(offset=(self.last_update_id + 1),
  File "C:\Users\paulo.welton\AppData\Local\Programs\Python\Python39\lib\site-packages\telebot\__init__.py", line 623, in get_updates
    json_updates = apihelper.get_updates(self.token, offset, limit, timeout, allowed_updates, long_polling_timeout)
  File "C:\Users\paulo.welton\AppData\Local\Programs\Python\Python39\lib\site-packages\telebot\apihelper.py", line 321, in get_updates
    return _make_request(token, method_url, params=payload)
  File "C:\Users\paulo.welton\AppData\Local\Programs\Python\Python39\lib\site-packages\telebot\apihelper.py", line 162, in _make_request
    json_result = _check_result(method_name, result)
  File "C:\Users\paulo.welton\AppData\Local\Programs\Python\Python39\lib\site-packages\telebot\apihelper.py", line 189, in _check_result
    raise ApiTelegramException(method_name, result, result_json)
telebot.apihelper.ApiTelegramException: A request to the Telegram API was unsuccessful. Error code: 409. Description: Conflict: can't use getUpdates method while webhook is active; use deleteWebhook to delete the webhook first

 09/04/2025 10:47:38 AM - ERROR - Threaded polling exception: A request to the Telegram API was unsuccessful. Error code: 409. Description: Conflict: can't use getUpdates method while webhook is active; use deleteWebhook to delete the webhook first
 09/04/2025 10:47:38 AM - ERROR - Exception traceback:
Traceback (most recent call last):
  File "C:\Users\paulo.welton\AppData\Local\Programs\Python\Python39\lib\site-packages\telebot\__init__.py", line 1073, in __threaded_polling
    polling_thread.raise_exceptions()
  File "C:\Users\paulo.welton\AppData\Local\Programs\Python\Python39\lib\site-packages\telebot\util.py", line 109, in raise_exceptions
    raise self.exception_info
  File "C:\Users\paulo.welton\AppData\Local\Programs\Python\Python39\lib\site-packages\telebot\util.py", line 91, in run
    task(*args, **kwargs)
  File "C:\Users\paulo.welton\AppData\Local\Programs\Python\Python39\lib\site-packages\telebot\__init__.py", line 649, in __retrieve_updates
    updates = self.get_updates(offset=(self.last_update_id + 1),
  File "C:\Users\paulo.welton\AppData\Local\Programs\Python\Python39\lib\site-packages\telebot\__init__.py", line 623, in get_updates
    json_updates = apihelper.get_updates(self.token, offset, limit, timeout, allowed_updates, long_polling_timeout)
  File "C:\Users\paulo.welton\AppData\Local\Programs\Python\Python39\lib\site-packages\telebot\apihelper.py", line 321, in get_updates
    return _make_request(token, method_url, params=payload)
  File "C:\Users\paulo.welton\AppData\Local\Programs\Python\Python39\lib\site-packages\telebot\apihelper.py", line 162, in _make_request
    json_result = _check_result(method_name, result)
  File "C:\Users\paulo.welton\AppData\Local\Programs\Python\Python39\lib\site-packages\telebot\apihelper.py", line 189, in _check_result
    raise ApiTelegramException(method_name, result, result_json)
telebot.apihelper.ApiTelegramException: A request to the Telegram API was unsuccessful. Error code: 409. Description: Conflict: can't use getUpdates method while webhook is active; use deleteWebhook to delete the webhook first

 09/04/2025 10:48:38 AM - ERROR - Threaded polling exception: A request to the Telegram API was unsuccessful. Error code: 409. Description: Conflict: can't use getUpdates method while webhook is active; use deleteWebhook to delete the webhook first
 09/04/2025 10:48:38 AM - ERROR - Exception traceback:
Traceback (most recent call last):
  File "C:\Users\paulo.welton\AppData\Local\Programs\Python\Python39\lib\site-packages\telebot\__init__.py", line 1073, in __threaded_polling
    polling_thread.raise_exceptions()
  File "C:\Users\paulo.welton\AppData\Local\Programs\Python\Python39\lib\site-packages\telebot\util.py", line 109, in raise_exceptions
    raise self.exception_info
  File "C:\Users\paulo.welton\AppData\Local\Programs\Python\Python39\lib\site-packages\telebot\util.py", line 91, in run
    task(*args, **kwargs)
  File "C:\Users\paulo.welton\AppData\Local\Programs\Python\Python39\lib\site-packages\telebot\__init__.py", line 649, in __retrieve_updates
    updates = self.get_updates(offset=(self.last_update_id + 1),
  File "C:\Users\paulo.welton\AppData\Local\Programs\Python\Python39\lib\site-packages\telebot\__init__.py", line 623, in get_updates
    json_updates = apihelper.get_updates(self.token, offset, limit, timeout, allowed_updates, long_polling_timeout)
  File "C:\Users\paulo.welton\AppData\Local\Programs\Python\Python39\lib\site-packages\telebot\apihelper.py", line 321, in get_updates
    return _make_request(token, method_url, params=payload)
  File "C:\Users\paulo.welton\AppData\Local\Programs\Python\Python39\lib\site-packages\telebot\apihelper.py", line 162, in _make_request
    json_result = _check_result(method_name, result)
  File "C:\Users\paulo.welton\AppData\Local\Programs\Python\Python39\lib\site-packages\telebot\apihelper.py", line 189, in _check_result
    raise ApiTelegramException(method_name, result, result_json)
telebot.apihelper.ApiTelegramException: A request to the Telegram API was unsuccessful. Error code: 409. Description: Conflict: can't use getUpdates method while webhook is active; use deleteWebhook to delete the webhook first

 09/04/2025 10:49:38 AM - ERROR - Threaded polling exception: A request to the Telegram API was unsuccessful. Error code: 409. Description: Conflict: can't use getUpdates method while webhook is active; use deleteWebhook to delete the webhook first
 09/04/2025 10:49:38 AM - ERROR - Exception traceback:
Traceback (most recent call last):
  File "C:\Users\paulo.welton\AppData\Local\Programs\Python\Python39\lib\site-packages\telebot\__init__.py", line 1073, in __threaded_polling
    polling_thread.raise_exceptions()
  File "C:\Users\paulo.welton\AppData\Local\Programs\Python\Python39\lib\site-packages\telebot\util.py", line 109, in raise_exceptions
    raise self.exception_info
  File "C:\Users\paulo.welton\AppData\Local\Programs\Python\Python39\lib\site-packages\telebot\util.py", line 91, in run
    task(*args, **kwargs)
  File "C:\Users\paulo.welton\AppData\Local\Programs\Python\Python39\lib\site-packages\telebot\__init__.py", line 649, in __retrieve_updates
    updates = self.get_updates(offset=(self.last_update_id + 1),
  File "C:\Users\paulo.welton\AppData\Local\Programs\Python\Python39\lib\site-packages\telebot\__init__.py", line 623, in get_updates
    json_updates = apihelper.get_updates(self.token, offset, limit, timeout, allowed_updates, long_polling_timeout)
  File "C:\Users\paulo.welton\AppData\Local\Programs\Python\Python39\lib\site-packages\telebot\apihelper.py", line 321, in get_updates
    return _make_request(token, method_url, params=payload)
  File "C:\Users\paulo.welton\AppData\Local\Programs\Python\Python39\lib\site-packages\telebot\apihelper.py", line 162, in _make_request
    json_result = _check_result(method_name, result)
  File "C:\Users\paulo.welton\AppData\Local\Programs\Python\Python39\lib\site-packages\telebot\apihelper.py", line 189, in _check_result
    raise ApiTelegramException(method_name, result, result_json)
telebot.apihelper.ApiTelegramException: A request to the Telegram API was unsuccessful. Error code: 409. Description: Conflict: can't use getUpdates method while webhook is active; use deleteWebhook to delete the webhook first

 09/04/2025 10:50:39 AM - ERROR - Threaded polling exception: A request to the Telegram API was unsuccessful. Error code: 409. Description: Conflict: can't use getUpdates method while webhook is active; use deleteWebhook to delete the webhook first
 09/04/2025 10:50:39 AM - ERROR - Exception traceback:
Traceback (most recent call last):
  File "C:\Users\paulo.welton\AppData\Local\Programs\Python\Python39\lib\site-packages\telebot\__init__.py", line 1073, in __threaded_polling
    polling_thread.raise_exceptions()
  File "C:\Users\paulo.welton\AppData\Local\Programs\Python\Python39\lib\site-packages\telebot\util.py", line 109, in raise_exceptions
    raise self.exception_info
  File "C:\Users\paulo.welton\AppData\Local\Programs\Python\Python39\lib\site-packages\telebot\util.py", line 91, in run
    task(*args, **kwargs)
  File "C:\Users\paulo.welton\AppData\Local\Programs\Python\Python39\lib\site-packages\telebot\__init__.py", line 649, in __retrieve_updates
    updates = self.get_updates(offset=(self.last_update_id + 1),
  File "C:\Users\paulo.welton\AppData\Local\Programs\Python\Python39\lib\site-packages\telebot\__init__.py", line 623, in get_updates
    json_updates = apihelper.get_updates(self.token, offset, limit, timeout, allowed_updates, long_polling_timeout)
  File "C:\Users\paulo.welton\AppData\Local\Programs\Python\Python39\lib\site-packages\telebot\apihelper.py", line 321, in get_updates
    return _make_request(token, method_url, params=payload)
  File "C:\Users\paulo.welton\AppData\Local\Programs\Python\Python39\lib\site-packages\telebot\apihelper.py", line 162, in _make_request
    json_result = _check_result(method_name, result)
  File "C:\Users\paulo.welton\AppData\Local\Programs\Python\Python39\lib\site-packages\telebot\apihelper.py", line 189, in _check_result
    raise ApiTelegramException(method_name, result, result_json)
telebot.apihelper.ApiTelegramException: A request to the Telegram API was unsuccessful. Error code: 409. Description: Conflict: can't use getUpdates method while webhook is active; use deleteWebhook to delete the webhook first

 09/04/2025 10:51:39 AM - ERROR - Threaded polling exception: A request to the Telegram API was unsuccessful. Error code: 409. Description: Conflict: can't use getUpdates method while webhook is active; use deleteWebhook to delete the webhook first
 09/04/2025 10:51:39 AM - ERROR - Exception traceback:
Traceback (most recent call last):
  File "C:\Users\paulo.welton\AppData\Local\Programs\Python\Python39\lib\site-packages\telebot\__init__.py", line 1073, in __threaded_polling
    polling_thread.raise_exceptions()
  File "C:\Users\paulo.welton\AppData\Local\Programs\Python\Python39\lib\site-packages\telebot\util.py", line 109, in raise_exceptions
    raise self.exception_info
  File "C:\Users\paulo.welton\AppData\Local\Programs\Python\Python39\lib\site-packages\telebot\util.py", line 91, in run
    task(*args, **kwargs)
  File "C:\Users\paulo.welton\AppData\Local\Programs\Python\Python39\lib\site-packages\telebot\__init__.py", line 649, in __retrieve_updates
    updates = self.get_updates(offset=(self.last_update_id + 1),
  File "C:\Users\paulo.welton\AppData\Local\Programs\Python\Python39\lib\site-packages\telebot\__init__.py", line 623, in get_updates
    json_updates = apihelper.get_updates(self.token, offset, limit, timeout, allowed_updates, long_polling_timeout)
  File "C:\Users\paulo.welton\AppData\Local\Programs\Python\Python39\lib\site-packages\telebot\apihelper.py", line 321, in get_updates
    return _make_request(token, method_url, params=payload)
  File "C:\Users\paulo.welton\AppData\Local\Programs\Python\Python39\lib\site-packages\telebot\apihelper.py", line 162, in _make_request
    json_result = _check_result(method_name, result)
  File "C:\Users\paulo.welton\AppData\Local\Programs\Python\Python39\lib\site-packages\telebot\apihelper.py", line 189, in _check_result
    raise ApiTelegramException(method_name, result, result_json)
telebot.apihelper.ApiTelegramException: A request to the Telegram API was unsuccessful. Error code: 409. Description: Conflict: can't use getUpdates method while webhook is active; use deleteWebhook to delete the webhook first

 09/04/2025 10:52:39 AM - ERROR - Threaded polling exception: A request to the Telegram API was unsuccessful. Error code: 409. Description: Conflict: can't use getUpdates method while webhook is active; use deleteWebhook to delete the webhook first
 09/04/2025 10:52:39 AM - ERROR - Exception traceback:
Traceback (most recent call last):
  File "C:\Users\paulo.welton\AppData\Local\Programs\Python\Python39\lib\site-packages\telebot\__init__.py", line 1073, in __threaded_polling
    polling_thread.raise_exceptions()
  File "C:\Users\paulo.welton\AppData\Local\Programs\Python\Python39\lib\site-packages\telebot\util.py", line 109, in raise_exceptions
    raise self.exception_info
  File "C:\Users\paulo.welton\AppData\Local\Programs\Python\Python39\lib\site-packages\telebot\util.py", line 91, in run
    task(*args, **kwargs)
  File "C:\Users\paulo.welton\AppData\Local\Programs\Python\Python39\lib\site-packages\telebot\__init__.py", line 649, in __retrieve_updates
    updates = self.get_updates(offset=(self.last_update_id + 1),
  File "C:\Users\paulo.welton\AppData\Local\Programs\Python\Python39\lib\site-packages\telebot\__init__.py", line 623, in get_updates
    json_updates = apihelper.get_updates(self.token, offset, limit, timeout, allowed_updates, long_polling_timeout)
  File "C:\Users\paulo.welton\AppData\Local\Programs\Python\Python39\lib\site-packages\telebot\apihelper.py", line 321, in get_updates
    return _make_request(token, method_url, params=payload)
  File "C:\Users\paulo.welton\AppData\Local\Programs\Python\Python39\lib\site-packages\telebot\apihelper.py", line 162, in _make_request
    json_result = _check_result(method_name, result)
  File "C:\Users\paulo.welton\AppData\Local\Programs\Python\Python39\lib\site-packages\telebot\apihelper.py", line 189, in _check_result
    raise ApiTelegramException(method_name, result, result_json)
telebot.apihelper.ApiTelegramException: A request to the Telegram API was unsuccessful. Error code: 409. Description: Conflict: can't use getUpdates method while webhook is active; use deleteWebhook to delete the webhook first

 09/04/2025 10:53:39 AM - ERROR - Threaded polling exception: A request to the Telegram API was unsuccessful. Error code: 409. Description: Conflict: can't use getUpdates method while webhook is active; use deleteWebhook to delete the webhook first
 09/04/2025 10:53:39 AM - ERROR - Exception traceback:
Traceback (most recent call last):
  File "C:\Users\paulo.welton\AppData\Local\Programs\Python\Python39\lib\site-packages\telebot\__init__.py", line 1073, in __threaded_polling
    polling_thread.raise_exceptions()
  File "C:\Users\paulo.welton\AppData\Local\Programs\Python\Python39\lib\site-packages\telebot\util.py", line 109, in raise_exceptions
    raise self.exception_info
  File "C:\Users\paulo.welton\AppData\Local\Programs\Python\Python39\lib\site-packages\telebot\util.py", line 91, in run
    task(*args, **kwargs)
  File "C:\Users\paulo.welton\AppData\Local\Programs\Python\Python39\lib\site-packages\telebot\__init__.py", line 649, in __retrieve_updates
    updates = self.get_updates(offset=(self.last_update_id + 1),
  File "C:\Users\paulo.welton\AppData\Local\Programs\Python\Python39\lib\site-packages\telebot\__init__.py", line 623, in get_updates
    json_updates = apihelper.get_updates(self.token, offset, limit, timeout, allowed_updates, long_polling_timeout)
  File "C:\Users\paulo.welton\AppData\Local\Programs\Python\Python39\lib\site-packages\telebot\apihelper.py", line 321, in get_updates
    return _make_request(token, method_url, params=payload)
  File "C:\Users\paulo.welton\AppData\Local\Programs\Python\Python39\lib\site-packages\telebot\apihelper.py", line 162, in _make_request
    json_result = _check_result(method_name, result)
  File "C:\Users\paulo.welton\AppData\Local\Programs\Python\Python39\lib\site-packages\telebot\apihelper.py", line 189, in _check_result
    raise ApiTelegramException(method_name, result, result_json)
telebot.apihelper.ApiTelegramException: A request to the Telegram API was unsuccessful. Error code: 409. Description: Conflict: can't use getUpdates method while webhook is active; use deleteWebhook to delete the webhook first

 09/04/2025 10:54:39 AM - ERROR - Threaded polling exception: A request to the Telegram API was unsuccessful. Error code: 409. Description: Conflict: can't use getUpdates method while webhook is active; use deleteWebhook to delete the webhook first
 09/04/2025 10:54:39 AM - ERROR - Exception traceback:
Traceback (most recent call last):
  File "C:\Users\paulo.welton\AppData\Local\Programs\Python\Python39\lib\site-packages\telebot\__init__.py", line 1073, in __threaded_polling
    polling_thread.raise_exceptions()
  File "C:\Users\paulo.welton\AppData\Local\Programs\Python\Python39\lib\site-packages\telebot\util.py", line 109, in raise_exceptions
    raise self.exception_info
  File "C:\Users\paulo.welton\AppData\Local\Programs\Python\Python39\lib\site-packages\telebot\util.py", line 91, in run
    task(*args, **kwargs)
  File "C:\Users\paulo.welton\AppData\Local\Programs\Python\Python39\lib\site-packages\telebot\__init__.py", line 649, in __retrieve_updates
    updates = self.get_updates(offset=(self.last_update_id + 1),
  File "C:\Users\paulo.welton\AppData\Local\Programs\Python\Python39\lib\site-packages\telebot\__init__.py", line 623, in get_updates
    json_updates = apihelper.get_updates(self.token, offset, limit, timeout, allowed_updates, long_polling_timeout)
  File "C:\Users\paulo.welton\AppData\Local\Programs\Python\Python39\lib\site-packages\telebot\apihelper.py", line 321, in get_updates
    return _make_request(token, method_url, params=payload)
  File "C:\Users\paulo.welton\AppData\Local\Programs\Python\Python39\lib\site-packages\telebot\apihelper.py", line 162, in _make_request
    json_result = _check_result(method_name, result)
  File "C:\Users\paulo.welton\AppData\Local\Programs\Python\Python39\lib\site-packages\telebot\apihelper.py", line 189, in _check_result
    raise ApiTelegramException(method_name, result, result_json)
telebot.apihelper.ApiTelegramException: A request to the Telegram API was unsuccessful. Error code: 409. Description: Conflict: can't use getUpdates method while webhook is active; use deleteWebhook to delete the webhook first

 09/04/2025 10:55:39 AM - ERROR - Threaded polling exception: A request to the Telegram API was unsuccessful. Error code: 409. Description: Conflict: can't use getUpdates method while webhook is active; use deleteWebhook to delete the webhook first
 09/04/2025 10:55:39 AM - ERROR - Exception traceback:
Traceback (most recent call last):
  File "C:\Users\paulo.welton\AppData\Local\Programs\Python\Python39\lib\site-packages\telebot\__init__.py", line 1073, in __threaded_polling
    polling_thread.raise_exceptions()
  File "C:\Users\paulo.welton\AppData\Local\Programs\Python\Python39\lib\site-packages\telebot\util.py", line 109, in raise_exceptions
    raise self.exception_info
  File "C:\Users\paulo.welton\AppData\Local\Programs\Python\Python39\lib\site-packages\telebot\util.py", line 91, in run
    task(*args, **kwargs)
  File "C:\Users\paulo.welton\AppData\Local\Programs\Python\Python39\lib\site-packages\telebot\__init__.py", line 649, in __retrieve_updates
    updates = self.get_updates(offset=(self.last_update_id + 1),
  File "C:\Users\paulo.welton\AppData\Local\Programs\Python\Python39\lib\site-packages\telebot\__init__.py", line 623, in get_updates
    json_updates = apihelper.get_updates(self.token, offset, limit, timeout, allowed_updates, long_polling_timeout)
  File "C:\Users\paulo.welton\AppData\Local\Programs\Python\Python39\lib\site-packages\telebot\apihelper.py", line 321, in get_updates
    return _make_request(token, method_url, params=payload)
  File "C:\Users\paulo.welton\AppData\Local\Programs\Python\Python39\lib\site-packages\telebot\apihelper.py", line 162, in _make_request
    json_result = _check_result(method_name, result)
  File "C:\Users\paulo.welton\AppData\Local\Programs\Python\Python39\lib\site-packages\telebot\apihelper.py", line 189, in _check_result
    raise ApiTelegramException(method_name, result, result_json)
telebot.apihelper.ApiTelegramException: A request to the Telegram API was unsuccessful. Error code: 409. Description: Conflict: can't use getUpdates method while webhook is active; use deleteWebhook to delete the webhook first

 09/04/2025 10:59:52 AM - INFO - BOT TELEGRAM YOUTUBE

 09/04/2025 10:59:52 AM - INFO - bot chamado
 09/04/2025 11:00:10 AM - INFO - usuario esta tentando fazer download
 09/04/2025 11:00:12 AM - INFO - FIZ_UM_MALWARE: https://youtu.be/4pobgFPm19c?si=_rY-xtWbi0HXw-hD
 09/04/2025 11:01:59 AM - INFO - o usuario pediu a opcao video
 09/04/2025 11:02:00 AM - INFO - caminho: C:\Users\paulo.welton\Desktop\bot_telegram_youtube\video\FIZ_UM_MALWARE.m4a
 09/04/2025 11:02:29 AM - INFO - ('Connection aborted.', ConnectionResetError(10054, 'Foi forçado o cancelamento de uma conexão existente pelo host remoto', None, 10054, None))
 09/04/2025 11:03:21 AM - INFO - usuario esta tentando fazer download
 09/04/2025 11:03:22 AM - INFO - Moonlight_on_the_River: https://youtu.be/1VYbKamjB-4?si=JDefe5VzpQPTCIS6
 09/04/2025 11:03:25 AM - INFO - usuario pediu a opcao audio
 09/04/2025 11:03:25 AM - INFO - baixando audio...
 09/04/2025 11:03:33 AM - INFO - caminho: C:\Users\paulo.welton\Desktop\bot_telegram_youtube\audio\Moonlight_on_the_River.m4a
 09/04/2025 11:03:50 AM - INFO - audio enviado

 09/04/2025 11:05:16 AM - INFO - usuario esta tentando fazer download
 09/04/2025 11:05:18 AM - INFO - 2ZDinizz_-_Coisas_Que_N_o_Aprendi_Contigo__Clipe_Oficial____PATRONO: https://youtu.be/fAIlEcAtfGU?si=iyCMF1bbzFY3nBVX
 09/04/2025 11:05:21 AM - INFO - usuario pediu a opcao audio
 09/04/2025 11:05:21 AM - INFO - baixando audio...
 09/04/2025 11:05:26 AM - INFO - caminho: C:\Users\paulo.welton\Desktop\bot_telegram_youtube\audio\2ZDinizz_-_Coisas_Que_N_o_Aprendi_Contigo__Clipe_Oficial____PATRONO.m4a
 09/04/2025 11:05:37 AM - INFO - audio enviado

 09/04/2025 11:08:13 AM - INFO - usuario esta tentando fazer download
 09/04/2025 11:08:15 AM - INFO - 04__Baco_Exu_do_Blues_-_20_Liga__es: https://youtu.be/Sq7pVppXesU?si=GMVKLMsH5GW4zwew
 09/04/2025 11:08:19 AM - INFO - usuario pediu a opcao audio
 09/04/2025 11:08:19 AM - INFO - baixando audio...
 09/04/2025 11:08:22 AM - INFO - caminho: C:\Users\paulo.welton\Desktop\bot_telegram_youtube\audio\04__Baco_Exu_do_Blues_-_20_Liga__es.m4a
 09/04/2025 11:08:30 AM - INFO - audio enviado

 09/04/2025 11:59:07 AM - INFO - BOT TELEGRAM YOUTUBE

 09/04/2025 11:59:07 AM - INFO - bot chamado
 09/04/2025 11:59:50 AM - INFO - usuario esta tentando fazer download
 09/04/2025 11:59:52 AM - INFO - LinkedIn_para_PROGRAMADORES_iniciantes__guia_pr_tico_: https://youtu.be/umI7sAvUeZ8?si=0Nj3OV88bMvn90HE
 09/04/2025 11:59:58 AM - INFO - o usuario pediu a opcao video
 09/04/2025 12:01:07 PM - INFO - BOT TELEGRAM YOUTUBE

 09/04/2025 12:01:07 PM - INFO - bot chamado
 09/04/2025 12:01:14 PM - INFO - usuario esta tentando fazer download
 09/04/2025 12:01:16 PM - INFO - LinkedIn_para_PROGRAMADORES_iniciantes__guia_pr_tico_: https://youtu.be/umI7sAvUeZ8?si=0Nj3OV88bMvn90HE
 09/04/2025 12:01:18 PM - INFO - o usuario pediu a opcao video
 09/04/2025 12:06:40 PM - INFO - BOT TELEGRAM YOUTUBE

 09/04/2025 12:06:40 PM - INFO - bot chamado
 09/04/2025 12:06:45 PM - INFO - usuario esta tentando fazer download
 09/04/2025 12:06:47 PM - INFO - LinkedIn_para_PROGRAMADORES_iniciantes__guia_pr_tico_: https://youtu.be/umI7sAvUeZ8?si=0Nj3OV88bMvn90HE
 09/04/2025 12:06:51 PM - INFO - o usuario pediu a opcao video
 09/04/2025 12:06:51 PM - INFO - 'NoneType' object has no attribute 'strip'
 09/04/2025 12:15:29 PM - ERROR - Threaded polling exception: A request to the Telegram API was unsuccessful. Error code: 409. Description: Conflict: terminated by setWebhook request
 09/04/2025 12:15:29 PM - ERROR - Exception traceback:
Traceback (most recent call last):
  File "C:\Users\paulo.welton\AppData\Local\Programs\Python\Python39\lib\site-packages\telebot\__init__.py", line 1073, in __threaded_polling
    polling_thread.raise_exceptions()
  File "C:\Users\paulo.welton\AppData\Local\Programs\Python\Python39\lib\site-packages\telebot\util.py", line 109, in raise_exceptions
    raise self.exception_info
  File "C:\Users\paulo.welton\AppData\Local\Programs\Python\Python39\lib\site-packages\telebot\util.py", line 91, in run
    task(*args, **kwargs)
  File "C:\Users\paulo.welton\AppData\Local\Programs\Python\Python39\lib\site-packages\telebot\__init__.py", line 649, in __retrieve_updates
    updates = self.get_updates(offset=(self.last_update_id + 1),
  File "C:\Users\paulo.welton\AppData\Local\Programs\Python\Python39\lib\site-packages\telebot\__init__.py", line 623, in get_updates
    json_updates = apihelper.get_updates(self.token, offset, limit, timeout, allowed_updates, long_polling_timeout)
  File "C:\Users\paulo.welton\AppData\Local\Programs\Python\Python39\lib\site-packages\telebot\apihelper.py", line 321, in get_updates
    return _make_request(token, method_url, params=payload)
  File "C:\Users\paulo.welton\AppData\Local\Programs\Python\Python39\lib\site-packages\telebot\apihelper.py", line 162, in _make_request
    json_result = _check_result(method_name, result)
  File "C:\Users\paulo.welton\AppData\Local\Programs\Python\Python39\lib\site-packages\telebot\apihelper.py", line 189, in _check_result
    raise ApiTelegramException(method_name, result, result_json)
telebot.apihelper.ApiTelegramException: A request to the Telegram API was unsuccessful. Error code: 409. Description: Conflict: terminated by setWebhook request

 09/04/2025 12:15:33 PM - ERROR - Threaded polling exception: A request to the Telegram API was unsuccessful. Error code: 409. Description: Conflict: can't use getUpdates method while webhook is active; use deleteWebhook to delete the webhook first
 09/04/2025 12:15:33 PM - ERROR - Exception traceback:
Traceback (most recent call last):
  File "C:\Users\paulo.welton\AppData\Local\Programs\Python\Python39\lib\site-packages\telebot\__init__.py", line 1073, in __threaded_polling
    polling_thread.raise_exceptions()
  File "C:\Users\paulo.welton\AppData\Local\Programs\Python\Python39\lib\site-packages\telebot\util.py", line 109, in raise_exceptions
    raise self.exception_info
  File "C:\Users\paulo.welton\AppData\Local\Programs\Python\Python39\lib\site-packages\telebot\util.py", line 91, in run
    task(*args, **kwargs)
  File "C:\Users\paulo.welton\AppData\Local\Programs\Python\Python39\lib\site-packages\telebot\__init__.py", line 649, in __retrieve_updates
    updates = self.get_updates(offset=(self.last_update_id + 1),
  File "C:\Users\paulo.welton\AppData\Local\Programs\Python\Python39\lib\site-packages\telebot\__init__.py", line 623, in get_updates
    json_updates = apihelper.get_updates(self.token, offset, limit, timeout, allowed_updates, long_polling_timeout)
  File "C:\Users\paulo.welton\AppData\Local\Programs\Python\Python39\lib\site-packages\telebot\apihelper.py", line 321, in get_updates
    return _make_request(token, method_url, params=payload)
  File "C:\Users\paulo.welton\AppData\Local\Programs\Python\Python39\lib\site-packages\telebot\apihelper.py", line 162, in _make_request
    json_result = _check_result(method_name, result)
  File "C:\Users\paulo.welton\AppData\Local\Programs\Python\Python39\lib\site-packages\telebot\apihelper.py", line 189, in _check_result
    raise ApiTelegramException(method_name, result, result_json)
telebot.apihelper.ApiTelegramException: A request to the Telegram API was unsuccessful. Error code: 409. Description: Conflict: can't use getUpdates method while webhook is active; use deleteWebhook to delete the webhook first

 09/04/2025 12:15:33 PM - ERROR - Threaded polling exception: A request to the Telegram API was unsuccessful. Error code: 409. Description: Conflict: can't use getUpdates method while webhook is active; use deleteWebhook to delete the webhook first
 09/04/2025 12:15:33 PM - ERROR - Exception traceback:
Traceback (most recent call last):
  File "C:\Users\paulo.welton\AppData\Local\Programs\Python\Python39\lib\site-packages\telebot\__init__.py", line 1073, in __threaded_polling
    polling_thread.raise_exceptions()
  File "C:\Users\paulo.welton\AppData\Local\Programs\Python\Python39\lib\site-packages\telebot\util.py", line 109, in raise_exceptions
    raise self.exception_info
  File "C:\Users\paulo.welton\AppData\Local\Programs\Python\Python39\lib\site-packages\telebot\util.py", line 91, in run
    task(*args, **kwargs)
  File "C:\Users\paulo.welton\AppData\Local\Programs\Python\Python39\lib\site-packages\telebot\__init__.py", line 649, in __retrieve_updates
    updates = self.get_updates(offset=(self.last_update_id + 1),
  File "C:\Users\paulo.welton\AppData\Local\Programs\Python\Python39\lib\site-packages\telebot\__init__.py", line 623, in get_updates
    json_updates = apihelper.get_updates(self.token, offset, limit, timeout, allowed_updates, long_polling_timeout)
  File "C:\Users\paulo.welton\AppData\Local\Programs\Python\Python39\lib\site-packages\telebot\apihelper.py", line 321, in get_updates
    return _make_request(token, method_url, params=payload)
  File "C:\Users\paulo.welton\AppData\Local\Programs\Python\Python39\lib\site-packages\telebot\apihelper.py", line 162, in _make_request
    json_result = _check_result(method_name, result)
  File "C:\Users\paulo.welton\AppData\Local\Programs\Python\Python39\lib\site-packages\telebot\apihelper.py", line 189, in _check_result
    raise ApiTelegramException(method_name, result, result_json)
telebot.apihelper.ApiTelegramException: A request to the Telegram API was unsuccessful. Error code: 409. Description: Conflict: can't use getUpdates method while webhook is active; use deleteWebhook to delete the webhook first

 09/04/2025 12:15:38 PM - ERROR - Threaded polling exception: A request to the Telegram API was unsuccessful. Error code: 409. Description: Conflict: can't use getUpdates method while webhook is active; use deleteWebhook to delete the webhook first
 09/04/2025 12:15:38 PM - ERROR - Exception traceback:
Traceback (most recent call last):
  File "C:\Users\paulo.welton\AppData\Local\Programs\Python\Python39\lib\site-packages\telebot\__init__.py", line 1073, in __threaded_polling
    polling_thread.raise_exceptions()
  File "C:\Users\paulo.welton\AppData\Local\Programs\Python\Python39\lib\site-packages\telebot\util.py", line 109, in raise_exceptions
    raise self.exception_info
  File "C:\Users\paulo.welton\AppData\Local\Programs\Python\Python39\lib\site-packages\telebot\util.py", line 91, in run
    task(*args, **kwargs)
  File "C:\Users\paulo.welton\AppData\Local\Programs\Python\Python39\lib\site-packages\telebot\__init__.py", line 649, in __retrieve_updates
    updates = self.get_updates(offset=(self.last_update_id + 1),
  File "C:\Users\paulo.welton\AppData\Local\Programs\Python\Python39\lib\site-packages\telebot\__init__.py", line 623, in get_updates
    json_updates = apihelper.get_updates(self.token, offset, limit, timeout, allowed_updates, long_polling_timeout)
  File "C:\Users\paulo.welton\AppData\Local\Programs\Python\Python39\lib\site-packages\telebot\apihelper.py", line 321, in get_updates
    return _make_request(token, method_url, params=payload)
  File "C:\Users\paulo.welton\AppData\Local\Programs\Python\Python39\lib\site-packages\telebot\apihelper.py", line 162, in _make_request
    json_result = _check_result(method_name, result)
  File "C:\Users\paulo.welton\AppData\Local\Programs\Python\Python39\lib\site-packages\telebot\apihelper.py", line 189, in _check_result
    raise ApiTelegramException(method_name, result, result_json)
telebot.apihelper.ApiTelegramException: A request to the Telegram API was unsuccessful. Error code: 409. Description: Conflict: can't use getUpdates method while webhook is active; use deleteWebhook to delete the webhook first

 09/04/2025 12:15:40 PM - ERROR - Threaded polling exception: A request to the Telegram API was unsuccessful. Error code: 409. Description: Conflict: can't use getUpdates method while webhook is active; use deleteWebhook to delete the webhook first
 09/04/2025 12:15:40 PM - ERROR - Exception traceback:
Traceback (most recent call last):
  File "C:\Users\paulo.welton\AppData\Local\Programs\Python\Python39\lib\site-packages\telebot\__init__.py", line 1073, in __threaded_polling
    polling_thread.raise_exceptions()
  File "C:\Users\paulo.welton\AppData\Local\Programs\Python\Python39\lib\site-packages\telebot\util.py", line 109, in raise_exceptions
    raise self.exception_info
  File "C:\Users\paulo.welton\AppData\Local\Programs\Python\Python39\lib\site-packages\telebot\util.py", line 91, in run
    task(*args, **kwargs)
  File "C:\Users\paulo.welton\AppData\Local\Programs\Python\Python39\lib\site-packages\telebot\__init__.py", line 649, in __retrieve_updates
    updates = self.get_updates(offset=(self.last_update_id + 1),
  File "C:\Users\paulo.welton\AppData\Local\Programs\Python\Python39\lib\site-packages\telebot\__init__.py", line 623, in get_updates
    json_updates = apihelper.get_updates(self.token, offset, limit, timeout, allowed_updates, long_polling_timeout)
  File "C:\Users\paulo.welton\AppData\Local\Programs\Python\Python39\lib\site-packages\telebot\apihelper.py", line 321, in get_updates
    return _make_request(token, method_url, params=payload)
  File "C:\Users\paulo.welton\AppData\Local\Programs\Python\Python39\lib\site-packages\telebot\apihelper.py", line 162, in _make_request
    json_result = _check_result(method_name, result)
  File "C:\Users\paulo.welton\AppData\Local\Programs\Python\Python39\lib\site-packages\telebot\apihelper.py", line 189, in _check_result
    raise ApiTelegramException(method_name, result, result_json)
telebot.apihelper.ApiTelegramException: A request to the Telegram API was unsuccessful. Error code: 409. Description: Conflict: can't use getUpdates method while webhook is active; use deleteWebhook to delete the webhook first

 09/04/2025 12:15:44 PM - ERROR - Threaded polling exception: A request to the Telegram API was unsuccessful. Error code: 409. Description: Conflict: can't use getUpdates method while webhook is active; use deleteWebhook to delete the webhook first
 09/04/2025 12:15:44 PM - ERROR - Exception traceback:
Traceback (most recent call last):
  File "C:\Users\paulo.welton\AppData\Local\Programs\Python\Python39\lib\site-packages\telebot\__init__.py", line 1073, in __threaded_polling
    polling_thread.raise_exceptions()
  File "C:\Users\paulo.welton\AppData\Local\Programs\Python\Python39\lib\site-packages\telebot\util.py", line 109, in raise_exceptions
    raise self.exception_info
  File "C:\Users\paulo.welton\AppData\Local\Programs\Python\Python39\lib\site-packages\telebot\util.py", line 91, in run
    task(*args, **kwargs)
  File "C:\Users\paulo.welton\AppData\Local\Programs\Python\Python39\lib\site-packages\telebot\__init__.py", line 649, in __retrieve_updates
    updates = self.get_updates(offset=(self.last_update_id + 1),
  File "C:\Users\paulo.welton\AppData\Local\Programs\Python\Python39\lib\site-packages\telebot\__init__.py", line 623, in get_updates
    json_updates = apihelper.get_updates(self.token, offset, limit, timeout, allowed_updates, long_polling_timeout)
  File "C:\Users\paulo.welton\AppData\Local\Programs\Python\Python39\lib\site-packages\telebot\apihelper.py", line 321, in get_updates
    return _make_request(token, method_url, params=payload)
  File "C:\Users\paulo.welton\AppData\Local\Programs\Python\Python39\lib\site-packages\telebot\apihelper.py", line 162, in _make_request
    json_result = _check_result(method_name, result)
  File "C:\Users\paulo.welton\AppData\Local\Programs\Python\Python39\lib\site-packages\telebot\apihelper.py", line 189, in _check_result
    raise ApiTelegramException(method_name, result, result_json)
telebot.apihelper.ApiTelegramException: A request to the Telegram API was unsuccessful. Error code: 409. Description: Conflict: can't use getUpdates method while webhook is active; use deleteWebhook to delete the webhook first

 09/04/2025 12:15:52 PM - ERROR - Threaded polling exception: A request to the Telegram API was unsuccessful. Error code: 409. Description: Conflict: can't use getUpdates method while webhook is active; use deleteWebhook to delete the webhook first
 09/04/2025 12:15:52 PM - ERROR - Exception traceback:
Traceback (most recent call last):
  File "C:\Users\paulo.welton\AppData\Local\Programs\Python\Python39\lib\site-packages\telebot\__init__.py", line 1073, in __threaded_polling
    polling_thread.raise_exceptions()
  File "C:\Users\paulo.welton\AppData\Local\Programs\Python\Python39\lib\site-packages\telebot\util.py", line 109, in raise_exceptions
    raise self.exception_info
  File "C:\Users\paulo.welton\AppData\Local\Programs\Python\Python39\lib\site-packages\telebot\util.py", line 91, in run
    task(*args, **kwargs)
  File "C:\Users\paulo.welton\AppData\Local\Programs\Python\Python39\lib\site-packages\telebot\__init__.py", line 649, in __retrieve_updates
    updates = self.get_updates(offset=(self.last_update_id + 1),
  File "C:\Users\paulo.welton\AppData\Local\Programs\Python\Python39\lib\site-packages\telebot\__init__.py", line 623, in get_updates
    json_updates = apihelper.get_updates(self.token, offset, limit, timeout, allowed_updates, long_polling_timeout)
  File "C:\Users\paulo.welton\AppData\Local\Programs\Python\Python39\lib\site-packages\telebot\apihelper.py", line 321, in get_updates
    return _make_request(token, method_url, params=payload)
  File "C:\Users\paulo.welton\AppData\Local\Programs\Python\Python39\lib\site-packages\telebot\apihelper.py", line 162, in _make_request
    json_result = _check_result(method_name, result)
  File "C:\Users\paulo.welton\AppData\Local\Programs\Python\Python39\lib\site-packages\telebot\apihelper.py", line 189, in _check_result
    raise ApiTelegramException(method_name, result, result_json)
telebot.apihelper.ApiTelegramException: A request to the Telegram API was unsuccessful. Error code: 409. Description: Conflict: can't use getUpdates method while webhook is active; use deleteWebhook to delete the webhook first

 11/04/2025 09:34:11 AM - INFO - BOT TELEGRAM YOUTUBE

 11/04/2025 09:34:11 AM - INFO - bot chamado
 11/04/2025 09:34:52 AM - INFO - usuario esta tentando fazer download
 11/04/2025 09:34:54 AM - INFO - ALEE_-_PAG_O_Ft__KLISMAN: https://youtu.be/EfJMGfM3c5Q?si=v_LBRmUKMXrfWB8I
 11/04/2025 09:34:57 AM - INFO - o usuario pediu a opcao video
 11/04/2025 09:35:29 AM - INFO - caminho: C:\Users\paulo.welton\Desktop\bot_telegram_youtube\video\ALEE_-_PAG_O_Ft__KLISMAN.m4a
 11/04/2025 09:59:30 AM - INFO - BOT TELEGRAM YOUTUBE

 11/04/2025 09:59:30 AM - INFO - bot chamado
 11/04/2025 09:59:38 AM - INFO - usuario esta tentando fazer download
 11/04/2025 09:59:39 AM - INFO - ALEE_-_PAG_O_Ft__KLISMAN: https://youtu.be/EfJMGfM3c5Q?si=v_LBRmUKMXrfWB8I
 11/04/2025 09:59:42 AM - INFO - o usuario pediu a opcao video
 11/04/2025 10:00:02 AM - INFO - caminho: C:\Users\paulo.welton\Desktop\bot_telegram_youtube\video\ALEE_-_PAG_O_Ft__KLISMAN.m4a
 11/04/2025 11:02:21 AM - INFO - BOT TELEGRAM YOUTUBE

 11/04/2025 11:02:21 AM - INFO - bot chamado
 11/04/2025 11:02:42 AM - INFO - usuario esta tentando fazer download
 11/04/2025 11:02:44 AM - INFO - ALEE_-_PAG_O_Ft__KLISMAN: https://youtu.be/EfJMGfM3c5Q?si=v_LBRmUKMXrfWB8I
 11/04/2025 11:02:50 AM - INFO - o usuario pediu a opcao video
 11/04/2025 11:02:50 AM - INFO - A request to the Telegram API was unsuccessful. Error code: 400. Description: Bad Request: can't parse entities: Unexpected end tag at byte offset 0
 11/04/2025 11:05:33 AM - INFO - usuario esta tentando fazer download
 11/04/2025 11:05:35 AM - INFO - ALEE_-_PAG_O_Ft__KLISMAN: https://youtu.be/EfJMGfM3c5Q?si=v_LBRmUKMXrfWB8I
 11/04/2025 11:05:37 AM - INFO - o usuario pediu a opcao video
 11/04/2025 11:05:37 AM - INFO - A request to the Telegram API was unsuccessful. Error code: 400. Description: Bad Request: can't parse entities: Unexpected end tag at byte offset 0
 11/04/2025 11:12:50 AM - INFO - BOT TELEGRAM YOUTUBE

 11/04/2025 11:12:50 AM - INFO - bot chamado
 11/04/2025 11:13:01 AM - INFO - usuario esta tentando fazer download
 11/04/2025 11:13:03 AM - INFO - ALEE_-_PAG_O_Ft__KLISMAN: https://youtu.be/EfJMGfM3c5Q?si=v_LBRmUKMXrfWB8I
 11/04/2025 11:13:05 AM - INFO - o usuario pediu a opcao video
 11/04/2025 11:13:15 AM - ERROR - Infinity polling exception: 'Message' object has no attribute 'next'
 11/04/2025 11:13:15 AM - ERROR - Exception traceback:
Traceback (most recent call last):
  File "C:\Users\paulo.welton\AppData\Local\Programs\Python\Python39\lib\site-packages\telebot\__init__.py", line 955, in infinity_polling
    self.polling(non_stop=True, timeout=timeout, long_polling_timeout=long_polling_timeout,
  File "C:\Users\paulo.welton\AppData\Local\Programs\Python\Python39\lib\site-packages\telebot\__init__.py", line 1043, in polling
    self.__threaded_polling(non_stop=non_stop, interval=interval, timeout=timeout, long_polling_timeout=long_polling_timeout,
  File "C:\Users\paulo.welton\AppData\Local\Programs\Python\Python39\lib\site-packages\telebot\__init__.py", line 1118, in __threaded_polling
    raise e
  File "C:\Users\paulo.welton\AppData\Local\Programs\Python\Python39\lib\site-packages\telebot\__init__.py", line 1074, in __threaded_polling
    self.worker_pool.raise_exceptions()
  File "C:\Users\paulo.welton\AppData\Local\Programs\Python\Python39\lib\site-packages\telebot\util.py", line 148, in raise_exceptions
    raise self.exception_info
  File "C:\Users\paulo.welton\AppData\Local\Programs\Python\Python39\lib\site-packages\telebot\util.py", line 91, in run
    task(*args, **kwargs)
  File "c:\Users\paulo.welton\Desktop\bot_telegram_youtube\src\model\bot.py", line 36, in processar_escolha
    escolha = message.next.strip()
AttributeError: 'Message' object has no attribute 'next'

 11/04/2025 11:17:20 AM - INFO - usuario esta tentando fazer download
 11/04/2025 11:17:22 AM - INFO - ALEE_-_PAG_O_Ft__KLISMAN: https://youtu.be/EfJMGfM3c5Q?si=v_LBRmUKMXrfWB8I
 11/04/2025 11:17:23 AM - INFO - o usuario pediu a opcao video
 11/04/2025 11:17:27 AM - ERROR - Infinity polling exception: 'Message' object has no attribute 'next'
 11/04/2025 11:17:27 AM - ERROR - Exception traceback:
Traceback (most recent call last):
  File "C:\Users\paulo.welton\AppData\Local\Programs\Python\Python39\lib\site-packages\telebot\__init__.py", line 955, in infinity_polling
    self.polling(non_stop=True, timeout=timeout, long_polling_timeout=long_polling_timeout,
  File "C:\Users\paulo.welton\AppData\Local\Programs\Python\Python39\lib\site-packages\telebot\__init__.py", line 1043, in polling
    self.__threaded_polling(non_stop=non_stop, interval=interval, timeout=timeout, long_polling_timeout=long_polling_timeout,
  File "C:\Users\paulo.welton\AppData\Local\Programs\Python\Python39\lib\site-packages\telebot\__init__.py", line 1118, in __threaded_polling
    raise e
  File "C:\Users\paulo.welton\AppData\Local\Programs\Python\Python39\lib\site-packages\telebot\__init__.py", line 1074, in __threaded_polling
    self.worker_pool.raise_exceptions()
  File "C:\Users\paulo.welton\AppData\Local\Programs\Python\Python39\lib\site-packages\telebot\util.py", line 148, in raise_exceptions
    raise self.exception_info
  File "C:\Users\paulo.welton\AppData\Local\Programs\Python\Python39\lib\site-packages\telebot\util.py", line 91, in run
    task(*args, **kwargs)
  File "c:\Users\paulo.welton\Desktop\bot_telegram_youtube\src\model\bot.py", line 36, in processar_escolha
    escolha = message.next.strip()
AttributeError: 'Message' object has no attribute 'next'

 11/04/2025 11:17:48 AM - INFO - BOT TELEGRAM YOUTUBE

 11/04/2025 11:17:48 AM - INFO - bot chamado
 11/04/2025 11:17:52 AM - INFO - usuario esta tentando fazer download
 11/04/2025 11:17:54 AM - INFO - ALEE_-_PAG_O_Ft__KLISMAN: https://youtu.be/EfJMGfM3c5Q?si=v_LBRmUKMXrfWB8I
 11/04/2025 11:17:56 AM - INFO - o usuario pediu a opcao video
 11/04/2025 11:18:38 AM - INFO - BOT TELEGRAM YOUTUBE

 11/04/2025 11:18:38 AM - INFO - bot chamado
 11/04/2025 11:18:40 AM - INFO - usuario esta tentando fazer download
 11/04/2025 11:18:42 AM - INFO - ALEE_-_PAG_O_Ft__KLISMAN: https://youtu.be/EfJMGfM3c5Q?si=v_LBRmUKMXrfWB8I
 11/04/2025 11:18:44 AM - INFO - o usuario pediu a opcao video
 11/04/2025 11:19:07 AM - INFO - BOT TELEGRAM YOUTUBE

 11/04/2025 11:19:07 AM - INFO - bot chamado
 11/04/2025 11:19:30 AM - INFO - usuario esta tentando fazer download
 11/04/2025 11:19:32 AM - INFO - ALEE_-_PAG_O_Ft__KLISMAN: https://youtu.be/EfJMGfM3c5Q?si=v_LBRmUKMXrfWB8I
 11/04/2025 11:19:35 AM - INFO - o usuario pediu a opcao video
 11/04/2025 11:19:38 AM - ERROR - Infinity polling exception: 6490586194
 11/04/2025 11:19:38 AM - ERROR - Exception traceback:
Traceback (most recent call last):
  File "C:\Users\paulo.welton\AppData\Local\Programs\Python\Python39\lib\site-packages\telebot\__init__.py", line 955, in infinity_polling
    self.polling(non_stop=True, timeout=timeout, long_polling_timeout=long_polling_timeout,
  File "C:\Users\paulo.welton\AppData\Local\Programs\Python\Python39\lib\site-packages\telebot\__init__.py", line 1043, in polling
    self.__threaded_polling(non_stop=non_stop, interval=interval, timeout=timeout, long_polling_timeout=long_polling_timeout,
  File "C:\Users\paulo.welton\AppData\Local\Programs\Python\Python39\lib\site-packages\telebot\__init__.py", line 1118, in __threaded_polling
    raise e
  File "C:\Users\paulo.welton\AppData\Local\Programs\Python\Python39\lib\site-packages\telebot\__init__.py", line 1074, in __threaded_polling
    self.worker_pool.raise_exceptions()
  File "C:\Users\paulo.welton\AppData\Local\Programs\Python\Python39\lib\site-packages\telebot\util.py", line 148, in raise_exceptions
    raise self.exception_info
  File "C:\Users\paulo.welton\AppData\Local\Programs\Python\Python39\lib\site-packages\telebot\util.py", line 91, in run
    task(*args, **kwargs)
  File "c:\Users\paulo.welton\Desktop\bot_telegram_youtube\src\model\bot.py", line 46, in processar_escolha
    bot.register_next_step_handler(message, enviar_video_via_email, user_data[chat_id])
KeyError: 6490586194

 11/04/2025 11:35:49 AM - ERROR - Threaded polling exception: A request to the Telegram API was unsuccessful. Error code: 409. Description: Conflict: terminated by setWebhook request
 11/04/2025 11:35:49 AM - ERROR - Exception traceback:
Traceback (most recent call last):
  File "C:\Users\paulo.welton\AppData\Local\Programs\Python\Python39\lib\site-packages\telebot\__init__.py", line 1073, in __threaded_polling
    polling_thread.raise_exceptions()
  File "C:\Users\paulo.welton\AppData\Local\Programs\Python\Python39\lib\site-packages\telebot\util.py", line 109, in raise_exceptions
    raise self.exception_info
  File "C:\Users\paulo.welton\AppData\Local\Programs\Python\Python39\lib\site-packages\telebot\util.py", line 91, in run
    task(*args, **kwargs)
  File "C:\Users\paulo.welton\AppData\Local\Programs\Python\Python39\lib\site-packages\telebot\__init__.py", line 649, in __retrieve_updates
    updates = self.get_updates(offset=(self.last_update_id + 1),
  File "C:\Users\paulo.welton\AppData\Local\Programs\Python\Python39\lib\site-packages\telebot\__init__.py", line 623, in get_updates
    json_updates = apihelper.get_updates(self.token, offset, limit, timeout, allowed_updates, long_polling_timeout)
  File "C:\Users\paulo.welton\AppData\Local\Programs\Python\Python39\lib\site-packages\telebot\apihelper.py", line 321, in get_updates
    return _make_request(token, method_url, params=payload)
  File "C:\Users\paulo.welton\AppData\Local\Programs\Python\Python39\lib\site-packages\telebot\apihelper.py", line 162, in _make_request
    json_result = _check_result(method_name, result)
  File "C:\Users\paulo.welton\AppData\Local\Programs\Python\Python39\lib\site-packages\telebot\apihelper.py", line 189, in _check_result
    raise ApiTelegramException(method_name, result, result_json)
telebot.apihelper.ApiTelegramException: A request to the Telegram API was unsuccessful. Error code: 409. Description: Conflict: terminated by setWebhook request

 11/04/2025 11:35:53 AM - ERROR - Threaded polling exception: A request to the Telegram API was unsuccessful. Error code: 409. Description: Conflict: can't use getUpdates method while webhook is active; use deleteWebhook to delete the webhook first
 11/04/2025 11:35:53 AM - ERROR - Exception traceback:
Traceback (most recent call last):
  File "C:\Users\paulo.welton\AppData\Local\Programs\Python\Python39\lib\site-packages\telebot\__init__.py", line 1073, in __threaded_polling
    polling_thread.raise_exceptions()
  File "C:\Users\paulo.welton\AppData\Local\Programs\Python\Python39\lib\site-packages\telebot\util.py", line 109, in raise_exceptions
    raise self.exception_info
  File "C:\Users\paulo.welton\AppData\Local\Programs\Python\Python39\lib\site-packages\telebot\util.py", line 91, in run
    task(*args, **kwargs)
  File "C:\Users\paulo.welton\AppData\Local\Programs\Python\Python39\lib\site-packages\telebot\__init__.py", line 649, in __retrieve_updates
    updates = self.get_updates(offset=(self.last_update_id + 1),
  File "C:\Users\paulo.welton\AppData\Local\Programs\Python\Python39\lib\site-packages\telebot\__init__.py", line 623, in get_updates
    json_updates = apihelper.get_updates(self.token, offset, limit, timeout, allowed_updates, long_polling_timeout)
  File "C:\Users\paulo.welton\AppData\Local\Programs\Python\Python39\lib\site-packages\telebot\apihelper.py", line 321, in get_updates
    return _make_request(token, method_url, params=payload)
  File "C:\Users\paulo.welton\AppData\Local\Programs\Python\Python39\lib\site-packages\telebot\apihelper.py", line 162, in _make_request
    json_result = _check_result(method_name, result)
  File "C:\Users\paulo.welton\AppData\Local\Programs\Python\Python39\lib\site-packages\telebot\apihelper.py", line 189, in _check_result
    raise ApiTelegramException(method_name, result, result_json)
telebot.apihelper.ApiTelegramException: A request to the Telegram API was unsuccessful. Error code: 409. Description: Conflict: can't use getUpdates method while webhook is active; use deleteWebhook to delete the webhook first

 11/04/2025 11:35:54 AM - ERROR - Threaded polling exception: A request to the Telegram API was unsuccessful. Error code: 409. Description: Conflict: can't use getUpdates method while webhook is active; use deleteWebhook to delete the webhook first
 11/04/2025 11:35:54 AM - ERROR - Exception traceback:
Traceback (most recent call last):
  File "C:\Users\paulo.welton\AppData\Local\Programs\Python\Python39\lib\site-packages\telebot\__init__.py", line 1073, in __threaded_polling
    polling_thread.raise_exceptions()
  File "C:\Users\paulo.welton\AppData\Local\Programs\Python\Python39\lib\site-packages\telebot\util.py", line 109, in raise_exceptions
    raise self.exception_info
  File "C:\Users\paulo.welton\AppData\Local\Programs\Python\Python39\lib\site-packages\telebot\util.py", line 91, in run
    task(*args, **kwargs)
  File "C:\Users\paulo.welton\AppData\Local\Programs\Python\Python39\lib\site-packages\telebot\__init__.py", line 649, in __retrieve_updates
    updates = self.get_updates(offset=(self.last_update_id + 1),
  File "C:\Users\paulo.welton\AppData\Local\Programs\Python\Python39\lib\site-packages\telebot\__init__.py", line 623, in get_updates
    json_updates = apihelper.get_updates(self.token, offset, limit, timeout, allowed_updates, long_polling_timeout)
  File "C:\Users\paulo.welton\AppData\Local\Programs\Python\Python39\lib\site-packages\telebot\apihelper.py", line 321, in get_updates
    return _make_request(token, method_url, params=payload)
  File "C:\Users\paulo.welton\AppData\Local\Programs\Python\Python39\lib\site-packages\telebot\apihelper.py", line 162, in _make_request
    json_result = _check_result(method_name, result)
  File "C:\Users\paulo.welton\AppData\Local\Programs\Python\Python39\lib\site-packages\telebot\apihelper.py", line 189, in _check_result
    raise ApiTelegramException(method_name, result, result_json)
telebot.apihelper.ApiTelegramException: A request to the Telegram API was unsuccessful. Error code: 409. Description: Conflict: can't use getUpdates method while webhook is active; use deleteWebhook to delete the webhook first

 11/04/2025 11:35:58 AM - ERROR - Threaded polling exception: A request to the Telegram API was unsuccessful. Error code: 409. Description: Conflict: can't use getUpdates method while webhook is active; use deleteWebhook to delete the webhook first
 11/04/2025 11:35:58 AM - ERROR - Exception traceback:
Traceback (most recent call last):
  File "C:\Users\paulo.welton\AppData\Local\Programs\Python\Python39\lib\site-packages\telebot\__init__.py", line 1073, in __threaded_polling
    polling_thread.raise_exceptions()
  File "C:\Users\paulo.welton\AppData\Local\Programs\Python\Python39\lib\site-packages\telebot\util.py", line 109, in raise_exceptions
    raise self.exception_info
  File "C:\Users\paulo.welton\AppData\Local\Programs\Python\Python39\lib\site-packages\telebot\util.py", line 91, in run
    task(*args, **kwargs)
  File "C:\Users\paulo.welton\AppData\Local\Programs\Python\Python39\lib\site-packages\telebot\__init__.py", line 649, in __retrieve_updates
    updates = self.get_updates(offset=(self.last_update_id + 1),
  File "C:\Users\paulo.welton\AppData\Local\Programs\Python\Python39\lib\site-packages\telebot\__init__.py", line 623, in get_updates
    json_updates = apihelper.get_updates(self.token, offset, limit, timeout, allowed_updates, long_polling_timeout)
  File "C:\Users\paulo.welton\AppData\Local\Programs\Python\Python39\lib\site-packages\telebot\apihelper.py", line 321, in get_updates
    return _make_request(token, method_url, params=payload)
  File "C:\Users\paulo.welton\AppData\Local\Programs\Python\Python39\lib\site-packages\telebot\apihelper.py", line 162, in _make_request
    json_result = _check_result(method_name, result)
  File "C:\Users\paulo.welton\AppData\Local\Programs\Python\Python39\lib\site-packages\telebot\apihelper.py", line 189, in _check_result
    raise ApiTelegramException(method_name, result, result_json)
telebot.apihelper.ApiTelegramException: A request to the Telegram API was unsuccessful. Error code: 409. Description: Conflict: can't use getUpdates method while webhook is active; use deleteWebhook to delete the webhook first

 11/04/2025 11:36:00 AM - ERROR - Threaded polling exception: A request to the Telegram API was unsuccessful. Error code: 409. Description: Conflict: can't use getUpdates method while webhook is active; use deleteWebhook to delete the webhook first
 11/04/2025 11:36:00 AM - ERROR - Exception traceback:
Traceback (most recent call last):
  File "C:\Users\paulo.welton\AppData\Local\Programs\Python\Python39\lib\site-packages\telebot\__init__.py", line 1073, in __threaded_polling
    polling_thread.raise_exceptions()
  File "C:\Users\paulo.welton\AppData\Local\Programs\Python\Python39\lib\site-packages\telebot\util.py", line 109, in raise_exceptions
    raise self.exception_info
  File "C:\Users\paulo.welton\AppData\Local\Programs\Python\Python39\lib\site-packages\telebot\util.py", line 91, in run
    task(*args, **kwargs)
  File "C:\Users\paulo.welton\AppData\Local\Programs\Python\Python39\lib\site-packages\telebot\__init__.py", line 649, in __retrieve_updates
    updates = self.get_updates(offset=(self.last_update_id + 1),
  File "C:\Users\paulo.welton\AppData\Local\Programs\Python\Python39\lib\site-packages\telebot\__init__.py", line 623, in get_updates
    json_updates = apihelper.get_updates(self.token, offset, limit, timeout, allowed_updates, long_polling_timeout)
  File "C:\Users\paulo.welton\AppData\Local\Programs\Python\Python39\lib\site-packages\telebot\apihelper.py", line 321, in get_updates
    return _make_request(token, method_url, params=payload)
  File "C:\Users\paulo.welton\AppData\Local\Programs\Python\Python39\lib\site-packages\telebot\apihelper.py", line 162, in _make_request
    json_result = _check_result(method_name, result)
  File "C:\Users\paulo.welton\AppData\Local\Programs\Python\Python39\lib\site-packages\telebot\apihelper.py", line 189, in _check_result
    raise ApiTelegramException(method_name, result, result_json)
telebot.apihelper.ApiTelegramException: A request to the Telegram API was unsuccessful. Error code: 409. Description: Conflict: can't use getUpdates method while webhook is active; use deleteWebhook to delete the webhook first

 11/04/2025 11:36:04 AM - ERROR - Threaded polling exception: A request to the Telegram API was unsuccessful. Error code: 409. Description: Conflict: can't use getUpdates method while webhook is active; use deleteWebhook to delete the webhook first
 11/04/2025 11:36:04 AM - ERROR - Exception traceback:
Traceback (most recent call last):
  File "C:\Users\paulo.welton\AppData\Local\Programs\Python\Python39\lib\site-packages\telebot\__init__.py", line 1073, in __threaded_polling
    polling_thread.raise_exceptions()
  File "C:\Users\paulo.welton\AppData\Local\Programs\Python\Python39\lib\site-packages\telebot\util.py", line 109, in raise_exceptions
    raise self.exception_info
  File "C:\Users\paulo.welton\AppData\Local\Programs\Python\Python39\lib\site-packages\telebot\util.py", line 91, in run
    task(*args, **kwargs)
  File "C:\Users\paulo.welton\AppData\Local\Programs\Python\Python39\lib\site-packages\telebot\__init__.py", line 649, in __retrieve_updates
    updates = self.get_updates(offset=(self.last_update_id + 1),
  File "C:\Users\paulo.welton\AppData\Local\Programs\Python\Python39\lib\site-packages\telebot\__init__.py", line 623, in get_updates
    json_updates = apihelper.get_updates(self.token, offset, limit, timeout, allowed_updates, long_polling_timeout)
  File "C:\Users\paulo.welton\AppData\Local\Programs\Python\Python39\lib\site-packages\telebot\apihelper.py", line 321, in get_updates
    return _make_request(token, method_url, params=payload)
  File "C:\Users\paulo.welton\AppData\Local\Programs\Python\Python39\lib\site-packages\telebot\apihelper.py", line 162, in _make_request
    json_result = _check_result(method_name, result)
  File "C:\Users\paulo.welton\AppData\Local\Programs\Python\Python39\lib\site-packages\telebot\apihelper.py", line 189, in _check_result
    raise ApiTelegramException(method_name, result, result_json)
telebot.apihelper.ApiTelegramException: A request to the Telegram API was unsuccessful. Error code: 409. Description: Conflict: can't use getUpdates method while webhook is active; use deleteWebhook to delete the webhook first

 11/04/2025 11:36:12 AM - ERROR - Threaded polling exception: A request to the Telegram API was unsuccessful. Error code: 409. Description: Conflict: can't use getUpdates method while webhook is active; use deleteWebhook to delete the webhook first
 11/04/2025 11:36:12 AM - ERROR - Exception traceback:
Traceback (most recent call last):
  File "C:\Users\paulo.welton\AppData\Local\Programs\Python\Python39\lib\site-packages\telebot\__init__.py", line 1073, in __threaded_polling
    polling_thread.raise_exceptions()
  File "C:\Users\paulo.welton\AppData\Local\Programs\Python\Python39\lib\site-packages\telebot\util.py", line 109, in raise_exceptions
    raise self.exception_info
  File "C:\Users\paulo.welton\AppData\Local\Programs\Python\Python39\lib\site-packages\telebot\util.py", line 91, in run
    task(*args, **kwargs)
  File "C:\Users\paulo.welton\AppData\Local\Programs\Python\Python39\lib\site-packages\telebot\__init__.py", line 649, in __retrieve_updates
    updates = self.get_updates(offset=(self.last_update_id + 1),
  File "C:\Users\paulo.welton\AppData\Local\Programs\Python\Python39\lib\site-packages\telebot\__init__.py", line 623, in get_updates
    json_updates = apihelper.get_updates(self.token, offset, limit, timeout, allowed_updates, long_polling_timeout)
  File "C:\Users\paulo.welton\AppData\Local\Programs\Python\Python39\lib\site-packages\telebot\apihelper.py", line 321, in get_updates
    return _make_request(token, method_url, params=payload)
  File "C:\Users\paulo.welton\AppData\Local\Programs\Python\Python39\lib\site-packages\telebot\apihelper.py", line 162, in _make_request
    json_result = _check_result(method_name, result)
  File "C:\Users\paulo.welton\AppData\Local\Programs\Python\Python39\lib\site-packages\telebot\apihelper.py", line 189, in _check_result
    raise ApiTelegramException(method_name, result, result_json)
telebot.apihelper.ApiTelegramException: A request to the Telegram API was unsuccessful. Error code: 409. Description: Conflict: can't use getUpdates method while webhook is active; use deleteWebhook to delete the webhook first

 11/04/2025 11:36:28 AM - ERROR - Threaded polling exception: A request to the Telegram API was unsuccessful. Error code: 409. Description: Conflict: can't use getUpdates method while webhook is active; use deleteWebhook to delete the webhook first
 11/04/2025 11:36:28 AM - ERROR - Exception traceback:
Traceback (most recent call last):
  File "C:\Users\paulo.welton\AppData\Local\Programs\Python\Python39\lib\site-packages\telebot\__init__.py", line 1073, in __threaded_polling
    polling_thread.raise_exceptions()
  File "C:\Users\paulo.welton\AppData\Local\Programs\Python\Python39\lib\site-packages\telebot\util.py", line 109, in raise_exceptions
    raise self.exception_info
  File "C:\Users\paulo.welton\AppData\Local\Programs\Python\Python39\lib\site-packages\telebot\util.py", line 91, in run
    task(*args, **kwargs)
  File "C:\Users\paulo.welton\AppData\Local\Programs\Python\Python39\lib\site-packages\telebot\__init__.py", line 649, in __retrieve_updates
    updates = self.get_updates(offset=(self.last_update_id + 1),
  File "C:\Users\paulo.welton\AppData\Local\Programs\Python\Python39\lib\site-packages\telebot\__init__.py", line 623, in get_updates
    json_updates = apihelper.get_updates(self.token, offset, limit, timeout, allowed_updates, long_polling_timeout)
  File "C:\Users\paulo.welton\AppData\Local\Programs\Python\Python39\lib\site-packages\telebot\apihelper.py", line 321, in get_updates
    return _make_request(token, method_url, params=payload)
  File "C:\Users\paulo.welton\AppData\Local\Programs\Python\Python39\lib\site-packages\telebot\apihelper.py", line 162, in _make_request
    json_result = _check_result(method_name, result)
  File "C:\Users\paulo.welton\AppData\Local\Programs\Python\Python39\lib\site-packages\telebot\apihelper.py", line 189, in _check_result
    raise ApiTelegramException(method_name, result, result_json)
telebot.apihelper.ApiTelegramException: A request to the Telegram API was unsuccessful. Error code: 409. Description: Conflict: can't use getUpdates method while webhook is active; use deleteWebhook to delete the webhook first

 11/04/2025 11:37:01 AM - ERROR - Threaded polling exception: A request to the Telegram API was unsuccessful. Error code: 409. Description: Conflict: can't use getUpdates method while webhook is active; use deleteWebhook to delete the webhook first
 11/04/2025 11:37:01 AM - ERROR - Exception traceback:
Traceback (most recent call last):
  File "C:\Users\paulo.welton\AppData\Local\Programs\Python\Python39\lib\site-packages\telebot\__init__.py", line 1073, in __threaded_polling
    polling_thread.raise_exceptions()
  File "C:\Users\paulo.welton\AppData\Local\Programs\Python\Python39\lib\site-packages\telebot\util.py", line 109, in raise_exceptions
    raise self.exception_info
  File "C:\Users\paulo.welton\AppData\Local\Programs\Python\Python39\lib\site-packages\telebot\util.py", line 91, in run
    task(*args, **kwargs)
  File "C:\Users\paulo.welton\AppData\Local\Programs\Python\Python39\lib\site-packages\telebot\__init__.py", line 649, in __retrieve_updates
    updates = self.get_updates(offset=(self.last_update_id + 1),
  File "C:\Users\paulo.welton\AppData\Local\Programs\Python\Python39\lib\site-packages\telebot\__init__.py", line 623, in get_updates
    json_updates = apihelper.get_updates(self.token, offset, limit, timeout, allowed_updates, long_polling_timeout)
  File "C:\Users\paulo.welton\AppData\Local\Programs\Python\Python39\lib\site-packages\telebot\apihelper.py", line 321, in get_updates
    return _make_request(token, method_url, params=payload)
  File "C:\Users\paulo.welton\AppData\Local\Programs\Python\Python39\lib\site-packages\telebot\apihelper.py", line 162, in _make_request
    json_result = _check_result(method_name, result)
  File "C:\Users\paulo.welton\AppData\Local\Programs\Python\Python39\lib\site-packages\telebot\apihelper.py", line 189, in _check_result
    raise ApiTelegramException(method_name, result, result_json)
telebot.apihelper.ApiTelegramException: A request to the Telegram API was unsuccessful. Error code: 409. Description: Conflict: can't use getUpdates method while webhook is active; use deleteWebhook to delete the webhook first

 11/04/2025 11:38:01 AM - ERROR - Threaded polling exception: A request to the Telegram API was unsuccessful. Error code: 409. Description: Conflict: can't use getUpdates method while webhook is active; use deleteWebhook to delete the webhook first
 11/04/2025 11:38:01 AM - ERROR - Exception traceback:
Traceback (most recent call last):
  File "C:\Users\paulo.welton\AppData\Local\Programs\Python\Python39\lib\site-packages\telebot\__init__.py", line 1073, in __threaded_polling
    polling_thread.raise_exceptions()
  File "C:\Users\paulo.welton\AppData\Local\Programs\Python\Python39\lib\site-packages\telebot\util.py", line 109, in raise_exceptions
    raise self.exception_info
  File "C:\Users\paulo.welton\AppData\Local\Programs\Python\Python39\lib\site-packages\telebot\util.py", line 91, in run
    task(*args, **kwargs)
  File "C:\Users\paulo.welton\AppData\Local\Programs\Python\Python39\lib\site-packages\telebot\__init__.py", line 649, in __retrieve_updates
    updates = self.get_updates(offset=(self.last_update_id + 1),
  File "C:\Users\paulo.welton\AppData\Local\Programs\Python\Python39\lib\site-packages\telebot\__init__.py", line 623, in get_updates
    json_updates = apihelper.get_updates(self.token, offset, limit, timeout, allowed_updates, long_polling_timeout)
  File "C:\Users\paulo.welton\AppData\Local\Programs\Python\Python39\lib\site-packages\telebot\apihelper.py", line 321, in get_updates
    return _make_request(token, method_url, params=payload)
  File "C:\Users\paulo.welton\AppData\Local\Programs\Python\Python39\lib\site-packages\telebot\apihelper.py", line 162, in _make_request
    json_result = _check_result(method_name, result)
  File "C:\Users\paulo.welton\AppData\Local\Programs\Python\Python39\lib\site-packages\telebot\apihelper.py", line 189, in _check_result
    raise ApiTelegramException(method_name, result, result_json)
telebot.apihelper.ApiTelegramException: A request to the Telegram API was unsuccessful. Error code: 409. Description: Conflict: can't use getUpdates method while webhook is active; use deleteWebhook to delete the webhook first

 11/04/2025 11:39:01 AM - ERROR - Threaded polling exception: A request to the Telegram API was unsuccessful. Error code: 409. Description: Conflict: can't use getUpdates method while webhook is active; use deleteWebhook to delete the webhook first
 11/04/2025 11:39:01 AM - ERROR - Exception traceback:
Traceback (most recent call last):
  File "C:\Users\paulo.welton\AppData\Local\Programs\Python\Python39\lib\site-packages\telebot\__init__.py", line 1073, in __threaded_polling
    polling_thread.raise_exceptions()
  File "C:\Users\paulo.welton\AppData\Local\Programs\Python\Python39\lib\site-packages\telebot\util.py", line 109, in raise_exceptions
    raise self.exception_info
  File "C:\Users\paulo.welton\AppData\Local\Programs\Python\Python39\lib\site-packages\telebot\util.py", line 91, in run
    task(*args, **kwargs)
  File "C:\Users\paulo.welton\AppData\Local\Programs\Python\Python39\lib\site-packages\telebot\__init__.py", line 649, in __retrieve_updates
    updates = self.get_updates(offset=(self.last_update_id + 1),
  File "C:\Users\paulo.welton\AppData\Local\Programs\Python\Python39\lib\site-packages\telebot\__init__.py", line 623, in get_updates
    json_updates = apihelper.get_updates(self.token, offset, limit, timeout, allowed_updates, long_polling_timeout)
  File "C:\Users\paulo.welton\AppData\Local\Programs\Python\Python39\lib\site-packages\telebot\apihelper.py", line 321, in get_updates
    return _make_request(token, method_url, params=payload)
  File "C:\Users\paulo.welton\AppData\Local\Programs\Python\Python39\lib\site-packages\telebot\apihelper.py", line 162, in _make_request
    json_result = _check_result(method_name, result)
  File "C:\Users\paulo.welton\AppData\Local\Programs\Python\Python39\lib\site-packages\telebot\apihelper.py", line 189, in _check_result
    raise ApiTelegramException(method_name, result, result_json)
telebot.apihelper.ApiTelegramException: A request to the Telegram API was unsuccessful. Error code: 409. Description: Conflict: can't use getUpdates method while webhook is active; use deleteWebhook to delete the webhook first

 11/04/2025 11:40:01 AM - ERROR - Threaded polling exception: A request to the Telegram API was unsuccessful. Error code: 409. Description: Conflict: can't use getUpdates method while webhook is active; use deleteWebhook to delete the webhook first
 11/04/2025 11:40:01 AM - ERROR - Exception traceback:
Traceback (most recent call last):
  File "C:\Users\paulo.welton\AppData\Local\Programs\Python\Python39\lib\site-packages\telebot\__init__.py", line 1073, in __threaded_polling
    polling_thread.raise_exceptions()
  File "C:\Users\paulo.welton\AppData\Local\Programs\Python\Python39\lib\site-packages\telebot\util.py", line 109, in raise_exceptions
    raise self.exception_info
  File "C:\Users\paulo.welton\AppData\Local\Programs\Python\Python39\lib\site-packages\telebot\util.py", line 91, in run
    task(*args, **kwargs)
  File "C:\Users\paulo.welton\AppData\Local\Programs\Python\Python39\lib\site-packages\telebot\__init__.py", line 649, in __retrieve_updates
    updates = self.get_updates(offset=(self.last_update_id + 1),
  File "C:\Users\paulo.welton\AppData\Local\Programs\Python\Python39\lib\site-packages\telebot\__init__.py", line 623, in get_updates
    json_updates = apihelper.get_updates(self.token, offset, limit, timeout, allowed_updates, long_polling_timeout)
  File "C:\Users\paulo.welton\AppData\Local\Programs\Python\Python39\lib\site-packages\telebot\apihelper.py", line 321, in get_updates
    return _make_request(token, method_url, params=payload)
  File "C:\Users\paulo.welton\AppData\Local\Programs\Python\Python39\lib\site-packages\telebot\apihelper.py", line 162, in _make_request
    json_result = _check_result(method_name, result)
  File "C:\Users\paulo.welton\AppData\Local\Programs\Python\Python39\lib\site-packages\telebot\apihelper.py", line 189, in _check_result
    raise ApiTelegramException(method_name, result, result_json)
telebot.apihelper.ApiTelegramException: A request to the Telegram API was unsuccessful. Error code: 409. Description: Conflict: can't use getUpdates method while webhook is active; use deleteWebhook to delete the webhook first

 11/04/2025 11:41:02 AM - ERROR - Threaded polling exception: A request to the Telegram API was unsuccessful. Error code: 409. Description: Conflict: can't use getUpdates method while webhook is active; use deleteWebhook to delete the webhook first
 11/04/2025 11:41:02 AM - ERROR - Exception traceback:
Traceback (most recent call last):
  File "C:\Users\paulo.welton\AppData\Local\Programs\Python\Python39\lib\site-packages\telebot\__init__.py", line 1073, in __threaded_polling
    polling_thread.raise_exceptions()
  File "C:\Users\paulo.welton\AppData\Local\Programs\Python\Python39\lib\site-packages\telebot\util.py", line 109, in raise_exceptions
    raise self.exception_info
  File "C:\Users\paulo.welton\AppData\Local\Programs\Python\Python39\lib\site-packages\telebot\util.py", line 91, in run
    task(*args, **kwargs)
  File "C:\Users\paulo.welton\AppData\Local\Programs\Python\Python39\lib\site-packages\telebot\__init__.py", line 649, in __retrieve_updates
    updates = self.get_updates(offset=(self.last_update_id + 1),
  File "C:\Users\paulo.welton\AppData\Local\Programs\Python\Python39\lib\site-packages\telebot\__init__.py", line 623, in get_updates
    json_updates = apihelper.get_updates(self.token, offset, limit, timeout, allowed_updates, long_polling_timeout)
  File "C:\Users\paulo.welton\AppData\Local\Programs\Python\Python39\lib\site-packages\telebot\apihelper.py", line 321, in get_updates
    return _make_request(token, method_url, params=payload)
  File "C:\Users\paulo.welton\AppData\Local\Programs\Python\Python39\lib\site-packages\telebot\apihelper.py", line 162, in _make_request
    json_result = _check_result(method_name, result)
  File "C:\Users\paulo.welton\AppData\Local\Programs\Python\Python39\lib\site-packages\telebot\apihelper.py", line 189, in _check_result
    raise ApiTelegramException(method_name, result, result_json)
telebot.apihelper.ApiTelegramException: A request to the Telegram API was unsuccessful. Error code: 409. Description: Conflict: can't use getUpdates method while webhook is active; use deleteWebhook to delete the webhook first

 11/04/2025 11:42:02 AM - ERROR - Threaded polling exception: A request to the Telegram API was unsuccessful. Error code: 409. Description: Conflict: can't use getUpdates method while webhook is active; use deleteWebhook to delete the webhook first
 11/04/2025 11:42:02 AM - ERROR - Exception traceback:
Traceback (most recent call last):
  File "C:\Users\paulo.welton\AppData\Local\Programs\Python\Python39\lib\site-packages\telebot\__init__.py", line 1073, in __threaded_polling
    polling_thread.raise_exceptions()
  File "C:\Users\paulo.welton\AppData\Local\Programs\Python\Python39\lib\site-packages\telebot\util.py", line 109, in raise_exceptions
    raise self.exception_info
  File "C:\Users\paulo.welton\AppData\Local\Programs\Python\Python39\lib\site-packages\telebot\util.py", line 91, in run
    task(*args, **kwargs)
  File "C:\Users\paulo.welton\AppData\Local\Programs\Python\Python39\lib\site-packages\telebot\__init__.py", line 649, in __retrieve_updates
    updates = self.get_updates(offset=(self.last_update_id + 1),
  File "C:\Users\paulo.welton\AppData\Local\Programs\Python\Python39\lib\site-packages\telebot\__init__.py", line 623, in get_updates
    json_updates = apihelper.get_updates(self.token, offset, limit, timeout, allowed_updates, long_polling_timeout)
  File "C:\Users\paulo.welton\AppData\Local\Programs\Python\Python39\lib\site-packages\telebot\apihelper.py", line 321, in get_updates
    return _make_request(token, method_url, params=payload)
  File "C:\Users\paulo.welton\AppData\Local\Programs\Python\Python39\lib\site-packages\telebot\apihelper.py", line 162, in _make_request
    json_result = _check_result(method_name, result)
  File "C:\Users\paulo.welton\AppData\Local\Programs\Python\Python39\lib\site-packages\telebot\apihelper.py", line 189, in _check_result
    raise ApiTelegramException(method_name, result, result_json)
telebot.apihelper.ApiTelegramException: A request to the Telegram API was unsuccessful. Error code: 409. Description: Conflict: can't use getUpdates method while webhook is active; use deleteWebhook to delete the webhook first

 11/04/2025 11:43:02 AM - ERROR - Threaded polling exception: A request to the Telegram API was unsuccessful. Error code: 409. Description: Conflict: can't use getUpdates method while webhook is active; use deleteWebhook to delete the webhook first
 11/04/2025 11:43:02 AM - ERROR - Exception traceback:
Traceback (most recent call last):
  File "C:\Users\paulo.welton\AppData\Local\Programs\Python\Python39\lib\site-packages\telebot\__init__.py", line 1073, in __threaded_polling
    polling_thread.raise_exceptions()
  File "C:\Users\paulo.welton\AppData\Local\Programs\Python\Python39\lib\site-packages\telebot\util.py", line 109, in raise_exceptions
    raise self.exception_info
  File "C:\Users\paulo.welton\AppData\Local\Programs\Python\Python39\lib\site-packages\telebot\util.py", line 91, in run
    task(*args, **kwargs)
  File "C:\Users\paulo.welton\AppData\Local\Programs\Python\Python39\lib\site-packages\telebot\__init__.py", line 649, in __retrieve_updates
    updates = self.get_updates(offset=(self.last_update_id + 1),
  File "C:\Users\paulo.welton\AppData\Local\Programs\Python\Python39\lib\site-packages\telebot\__init__.py", line 623, in get_updates
    json_updates = apihelper.get_updates(self.token, offset, limit, timeout, allowed_updates, long_polling_timeout)
  File "C:\Users\paulo.welton\AppData\Local\Programs\Python\Python39\lib\site-packages\telebot\apihelper.py", line 321, in get_updates
    return _make_request(token, method_url, params=payload)
  File "C:\Users\paulo.welton\AppData\Local\Programs\Python\Python39\lib\site-packages\telebot\apihelper.py", line 162, in _make_request
    json_result = _check_result(method_name, result)
  File "C:\Users\paulo.welton\AppData\Local\Programs\Python\Python39\lib\site-packages\telebot\apihelper.py", line 189, in _check_result
    raise ApiTelegramException(method_name, result, result_json)
telebot.apihelper.ApiTelegramException: A request to the Telegram API was unsuccessful. Error code: 409. Description: Conflict: can't use getUpdates method while webhook is active; use deleteWebhook to delete the webhook first

 11/04/2025 11:44:02 AM - ERROR - Threaded polling exception: A request to the Telegram API was unsuccessful. Error code: 409. Description: Conflict: can't use getUpdates method while webhook is active; use deleteWebhook to delete the webhook first
 11/04/2025 11:44:02 AM - ERROR - Exception traceback:
Traceback (most recent call last):
  File "C:\Users\paulo.welton\AppData\Local\Programs\Python\Python39\lib\site-packages\telebot\__init__.py", line 1073, in __threaded_polling
    polling_thread.raise_exceptions()
  File "C:\Users\paulo.welton\AppData\Local\Programs\Python\Python39\lib\site-packages\telebot\util.py", line 109, in raise_exceptions
    raise self.exception_info
  File "C:\Users\paulo.welton\AppData\Local\Programs\Python\Python39\lib\site-packages\telebot\util.py", line 91, in run
    task(*args, **kwargs)
  File "C:\Users\paulo.welton\AppData\Local\Programs\Python\Python39\lib\site-packages\telebot\__init__.py", line 649, in __retrieve_updates
    updates = self.get_updates(offset=(self.last_update_id + 1),
  File "C:\Users\paulo.welton\AppData\Local\Programs\Python\Python39\lib\site-packages\telebot\__init__.py", line 623, in get_updates
    json_updates = apihelper.get_updates(self.token, offset, limit, timeout, allowed_updates, long_polling_timeout)
  File "C:\Users\paulo.welton\AppData\Local\Programs\Python\Python39\lib\site-packages\telebot\apihelper.py", line 321, in get_updates
    return _make_request(token, method_url, params=payload)
  File "C:\Users\paulo.welton\AppData\Local\Programs\Python\Python39\lib\site-packages\telebot\apihelper.py", line 162, in _make_request
    json_result = _check_result(method_name, result)
  File "C:\Users\paulo.welton\AppData\Local\Programs\Python\Python39\lib\site-packages\telebot\apihelper.py", line 189, in _check_result
    raise ApiTelegramException(method_name, result, result_json)
telebot.apihelper.ApiTelegramException: A request to the Telegram API was unsuccessful. Error code: 409. Description: Conflict: can't use getUpdates method while webhook is active; use deleteWebhook to delete the webhook first

 11/04/2025 11:45:02 AM - ERROR - Threaded polling exception: A request to the Telegram API was unsuccessful. Error code: 409. Description: Conflict: can't use getUpdates method while webhook is active; use deleteWebhook to delete the webhook first
 11/04/2025 11:45:02 AM - ERROR - Exception traceback:
Traceback (most recent call last):
  File "C:\Users\paulo.welton\AppData\Local\Programs\Python\Python39\lib\site-packages\telebot\__init__.py", line 1073, in __threaded_polling
    polling_thread.raise_exceptions()
  File "C:\Users\paulo.welton\AppData\Local\Programs\Python\Python39\lib\site-packages\telebot\util.py", line 109, in raise_exceptions
    raise self.exception_info
  File "C:\Users\paulo.welton\AppData\Local\Programs\Python\Python39\lib\site-packages\telebot\util.py", line 91, in run
    task(*args, **kwargs)
  File "C:\Users\paulo.welton\AppData\Local\Programs\Python\Python39\lib\site-packages\telebot\__init__.py", line 649, in __retrieve_updates
    updates = self.get_updates(offset=(self.last_update_id + 1),
  File "C:\Users\paulo.welton\AppData\Local\Programs\Python\Python39\lib\site-packages\telebot\__init__.py", line 623, in get_updates
    json_updates = apihelper.get_updates(self.token, offset, limit, timeout, allowed_updates, long_polling_timeout)
  File "C:\Users\paulo.welton\AppData\Local\Programs\Python\Python39\lib\site-packages\telebot\apihelper.py", line 321, in get_updates
    return _make_request(token, method_url, params=payload)
  File "C:\Users\paulo.welton\AppData\Local\Programs\Python\Python39\lib\site-packages\telebot\apihelper.py", line 162, in _make_request
    json_result = _check_result(method_name, result)
  File "C:\Users\paulo.welton\AppData\Local\Programs\Python\Python39\lib\site-packages\telebot\apihelper.py", line 189, in _check_result
    raise ApiTelegramException(method_name, result, result_json)
telebot.apihelper.ApiTelegramException: A request to the Telegram API was unsuccessful. Error code: 409. Description: Conflict: can't use getUpdates method while webhook is active; use deleteWebhook to delete the webhook first

 11/04/2025 11:46:03 AM - ERROR - Threaded polling exception: A request to the Telegram API was unsuccessful. Error code: 409. Description: Conflict: can't use getUpdates method while webhook is active; use deleteWebhook to delete the webhook first
 11/04/2025 11:46:03 AM - ERROR - Exception traceback:
Traceback (most recent call last):
  File "C:\Users\paulo.welton\AppData\Local\Programs\Python\Python39\lib\site-packages\telebot\__init__.py", line 1073, in __threaded_polling
    polling_thread.raise_exceptions()
  File "C:\Users\paulo.welton\AppData\Local\Programs\Python\Python39\lib\site-packages\telebot\util.py", line 109, in raise_exceptions
    raise self.exception_info
  File "C:\Users\paulo.welton\AppData\Local\Programs\Python\Python39\lib\site-packages\telebot\util.py", line 91, in run
    task(*args, **kwargs)
  File "C:\Users\paulo.welton\AppData\Local\Programs\Python\Python39\lib\site-packages\telebot\__init__.py", line 649, in __retrieve_updates
    updates = self.get_updates(offset=(self.last_update_id + 1),
  File "C:\Users\paulo.welton\AppData\Local\Programs\Python\Python39\lib\site-packages\telebot\__init__.py", line 623, in get_updates
    json_updates = apihelper.get_updates(self.token, offset, limit, timeout, allowed_updates, long_polling_timeout)
  File "C:\Users\paulo.welton\AppData\Local\Programs\Python\Python39\lib\site-packages\telebot\apihelper.py", line 321, in get_updates
    return _make_request(token, method_url, params=payload)
  File "C:\Users\paulo.welton\AppData\Local\Programs\Python\Python39\lib\site-packages\telebot\apihelper.py", line 162, in _make_request
    json_result = _check_result(method_name, result)
  File "C:\Users\paulo.welton\AppData\Local\Programs\Python\Python39\lib\site-packages\telebot\apihelper.py", line 189, in _check_result
    raise ApiTelegramException(method_name, result, result_json)
telebot.apihelper.ApiTelegramException: A request to the Telegram API was unsuccessful. Error code: 409. Description: Conflict: can't use getUpdates method while webhook is active; use deleteWebhook to delete the webhook first

 11/04/2025 11:47:03 AM - ERROR - Threaded polling exception: A request to the Telegram API was unsuccessful. Error code: 409. Description: Conflict: can't use getUpdates method while webhook is active; use deleteWebhook to delete the webhook first
 11/04/2025 11:47:03 AM - ERROR - Exception traceback:
Traceback (most recent call last):
  File "C:\Users\paulo.welton\AppData\Local\Programs\Python\Python39\lib\site-packages\telebot\__init__.py", line 1073, in __threaded_polling
    polling_thread.raise_exceptions()
  File "C:\Users\paulo.welton\AppData\Local\Programs\Python\Python39\lib\site-packages\telebot\util.py", line 109, in raise_exceptions
    raise self.exception_info
  File "C:\Users\paulo.welton\AppData\Local\Programs\Python\Python39\lib\site-packages\telebot\util.py", line 91, in run
    task(*args, **kwargs)
  File "C:\Users\paulo.welton\AppData\Local\Programs\Python\Python39\lib\site-packages\telebot\__init__.py", line 649, in __retrieve_updates
    updates = self.get_updates(offset=(self.last_update_id + 1),
  File "C:\Users\paulo.welton\AppData\Local\Programs\Python\Python39\lib\site-packages\telebot\__init__.py", line 623, in get_updates
    json_updates = apihelper.get_updates(self.token, offset, limit, timeout, allowed_updates, long_polling_timeout)
  File "C:\Users\paulo.welton\AppData\Local\Programs\Python\Python39\lib\site-packages\telebot\apihelper.py", line 321, in get_updates
    return _make_request(token, method_url, params=payload)
  File "C:\Users\paulo.welton\AppData\Local\Programs\Python\Python39\lib\site-packages\telebot\apihelper.py", line 162, in _make_request
    json_result = _check_result(method_name, result)
  File "C:\Users\paulo.welton\AppData\Local\Programs\Python\Python39\lib\site-packages\telebot\apihelper.py", line 189, in _check_result
    raise ApiTelegramException(method_name, result, result_json)
telebot.apihelper.ApiTelegramException: A request to the Telegram API was unsuccessful. Error code: 409. Description: Conflict: can't use getUpdates method while webhook is active; use deleteWebhook to delete the webhook first

 11/04/2025 11:48:03 AM - ERROR - Threaded polling exception: A request to the Telegram API was unsuccessful. Error code: 409. Description: Conflict: can't use getUpdates method while webhook is active; use deleteWebhook to delete the webhook first
 11/04/2025 11:48:03 AM - ERROR - Exception traceback:
Traceback (most recent call last):
  File "C:\Users\paulo.welton\AppData\Local\Programs\Python\Python39\lib\site-packages\telebot\__init__.py", line 1073, in __threaded_polling
    polling_thread.raise_exceptions()
  File "C:\Users\paulo.welton\AppData\Local\Programs\Python\Python39\lib\site-packages\telebot\util.py", line 109, in raise_exceptions
    raise self.exception_info
  File "C:\Users\paulo.welton\AppData\Local\Programs\Python\Python39\lib\site-packages\telebot\util.py", line 91, in run
    task(*args, **kwargs)
  File "C:\Users\paulo.welton\AppData\Local\Programs\Python\Python39\lib\site-packages\telebot\__init__.py", line 649, in __retrieve_updates
    updates = self.get_updates(offset=(self.last_update_id + 1),
  File "C:\Users\paulo.welton\AppData\Local\Programs\Python\Python39\lib\site-packages\telebot\__init__.py", line 623, in get_updates
    json_updates = apihelper.get_updates(self.token, offset, limit, timeout, allowed_updates, long_polling_timeout)
  File "C:\Users\paulo.welton\AppData\Local\Programs\Python\Python39\lib\site-packages\telebot\apihelper.py", line 321, in get_updates
    return _make_request(token, method_url, params=payload)
  File "C:\Users\paulo.welton\AppData\Local\Programs\Python\Python39\lib\site-packages\telebot\apihelper.py", line 162, in _make_request
    json_result = _check_result(method_name, result)
  File "C:\Users\paulo.welton\AppData\Local\Programs\Python\Python39\lib\site-packages\telebot\apihelper.py", line 189, in _check_result
    raise ApiTelegramException(method_name, result, result_json)
telebot.apihelper.ApiTelegramException: A request to the Telegram API was unsuccessful. Error code: 409. Description: Conflict: can't use getUpdates method while webhook is active; use deleteWebhook to delete the webhook first

 11/04/2025 11:49:03 AM - ERROR - Threaded polling exception: A request to the Telegram API was unsuccessful. Error code: 409. Description: Conflict: can't use getUpdates method while webhook is active; use deleteWebhook to delete the webhook first
 11/04/2025 11:49:03 AM - ERROR - Exception traceback:
Traceback (most recent call last):
  File "C:\Users\paulo.welton\AppData\Local\Programs\Python\Python39\lib\site-packages\telebot\__init__.py", line 1073, in __threaded_polling
    polling_thread.raise_exceptions()
  File "C:\Users\paulo.welton\AppData\Local\Programs\Python\Python39\lib\site-packages\telebot\util.py", line 109, in raise_exceptions
    raise self.exception_info
  File "C:\Users\paulo.welton\AppData\Local\Programs\Python\Python39\lib\site-packages\telebot\util.py", line 91, in run
    task(*args, **kwargs)
  File "C:\Users\paulo.welton\AppData\Local\Programs\Python\Python39\lib\site-packages\telebot\__init__.py", line 649, in __retrieve_updates
    updates = self.get_updates(offset=(self.last_update_id + 1),
  File "C:\Users\paulo.welton\AppData\Local\Programs\Python\Python39\lib\site-packages\telebot\__init__.py", line 623, in get_updates
    json_updates = apihelper.get_updates(self.token, offset, limit, timeout, allowed_updates, long_polling_timeout)
  File "C:\Users\paulo.welton\AppData\Local\Programs\Python\Python39\lib\site-packages\telebot\apihelper.py", line 321, in get_updates
    return _make_request(token, method_url, params=payload)
  File "C:\Users\paulo.welton\AppData\Local\Programs\Python\Python39\lib\site-packages\telebot\apihelper.py", line 162, in _make_request
    json_result = _check_result(method_name, result)
  File "C:\Users\paulo.welton\AppData\Local\Programs\Python\Python39\lib\site-packages\telebot\apihelper.py", line 189, in _check_result
    raise ApiTelegramException(method_name, result, result_json)
telebot.apihelper.ApiTelegramException: A request to the Telegram API was unsuccessful. Error code: 409. Description: Conflict: can't use getUpdates method while webhook is active; use deleteWebhook to delete the webhook first

 11/04/2025 11:50:03 AM - ERROR - Threaded polling exception: A request to the Telegram API was unsuccessful. Error code: 409. Description: Conflict: can't use getUpdates method while webhook is active; use deleteWebhook to delete the webhook first
 11/04/2025 11:50:03 AM - ERROR - Exception traceback:
Traceback (most recent call last):
  File "C:\Users\paulo.welton\AppData\Local\Programs\Python\Python39\lib\site-packages\telebot\__init__.py", line 1073, in __threaded_polling
    polling_thread.raise_exceptions()
  File "C:\Users\paulo.welton\AppData\Local\Programs\Python\Python39\lib\site-packages\telebot\util.py", line 109, in raise_exceptions
    raise self.exception_info
  File "C:\Users\paulo.welton\AppData\Local\Programs\Python\Python39\lib\site-packages\telebot\util.py", line 91, in run
    task(*args, **kwargs)
  File "C:\Users\paulo.welton\AppData\Local\Programs\Python\Python39\lib\site-packages\telebot\__init__.py", line 649, in __retrieve_updates
    updates = self.get_updates(offset=(self.last_update_id + 1),
  File "C:\Users\paulo.welton\AppData\Local\Programs\Python\Python39\lib\site-packages\telebot\__init__.py", line 623, in get_updates
    json_updates = apihelper.get_updates(self.token, offset, limit, timeout, allowed_updates, long_polling_timeout)
  File "C:\Users\paulo.welton\AppData\Local\Programs\Python\Python39\lib\site-packages\telebot\apihelper.py", line 321, in get_updates
    return _make_request(token, method_url, params=payload)
  File "C:\Users\paulo.welton\AppData\Local\Programs\Python\Python39\lib\site-packages\telebot\apihelper.py", line 162, in _make_request
    json_result = _check_result(method_name, result)
  File "C:\Users\paulo.welton\AppData\Local\Programs\Python\Python39\lib\site-packages\telebot\apihelper.py", line 189, in _check_result
    raise ApiTelegramException(method_name, result, result_json)
telebot.apihelper.ApiTelegramException: A request to the Telegram API was unsuccessful. Error code: 409. Description: Conflict: can't use getUpdates method while webhook is active; use deleteWebhook to delete the webhook first

 11/04/2025 11:51:04 AM - ERROR - Threaded polling exception: A request to the Telegram API was unsuccessful. Error code: 409. Description: Conflict: can't use getUpdates method while webhook is active; use deleteWebhook to delete the webhook first
 11/04/2025 11:51:04 AM - ERROR - Exception traceback:
Traceback (most recent call last):
  File "C:\Users\paulo.welton\AppData\Local\Programs\Python\Python39\lib\site-packages\telebot\__init__.py", line 1073, in __threaded_polling
    polling_thread.raise_exceptions()
  File "C:\Users\paulo.welton\AppData\Local\Programs\Python\Python39\lib\site-packages\telebot\util.py", line 109, in raise_exceptions
    raise self.exception_info
  File "C:\Users\paulo.welton\AppData\Local\Programs\Python\Python39\lib\site-packages\telebot\util.py", line 91, in run
    task(*args, **kwargs)
  File "C:\Users\paulo.welton\AppData\Local\Programs\Python\Python39\lib\site-packages\telebot\__init__.py", line 649, in __retrieve_updates
    updates = self.get_updates(offset=(self.last_update_id + 1),
  File "C:\Users\paulo.welton\AppData\Local\Programs\Python\Python39\lib\site-packages\telebot\__init__.py", line 623, in get_updates
    json_updates = apihelper.get_updates(self.token, offset, limit, timeout, allowed_updates, long_polling_timeout)
  File "C:\Users\paulo.welton\AppData\Local\Programs\Python\Python39\lib\site-packages\telebot\apihelper.py", line 321, in get_updates
    return _make_request(token, method_url, params=payload)
  File "C:\Users\paulo.welton\AppData\Local\Programs\Python\Python39\lib\site-packages\telebot\apihelper.py", line 162, in _make_request
    json_result = _check_result(method_name, result)
  File "C:\Users\paulo.welton\AppData\Local\Programs\Python\Python39\lib\site-packages\telebot\apihelper.py", line 189, in _check_result
    raise ApiTelegramException(method_name, result, result_json)
telebot.apihelper.ApiTelegramException: A request to the Telegram API was unsuccessful. Error code: 409. Description: Conflict: can't use getUpdates method while webhook is active; use deleteWebhook to delete the webhook first

 11/04/2025 11:52:04 AM - ERROR - Threaded polling exception: A request to the Telegram API was unsuccessful. Error code: 409. Description: Conflict: can't use getUpdates method while webhook is active; use deleteWebhook to delete the webhook first
 11/04/2025 11:52:04 AM - ERROR - Exception traceback:
Traceback (most recent call last):
  File "C:\Users\paulo.welton\AppData\Local\Programs\Python\Python39\lib\site-packages\telebot\__init__.py", line 1073, in __threaded_polling
    polling_thread.raise_exceptions()
  File "C:\Users\paulo.welton\AppData\Local\Programs\Python\Python39\lib\site-packages\telebot\util.py", line 109, in raise_exceptions
    raise self.exception_info
  File "C:\Users\paulo.welton\AppData\Local\Programs\Python\Python39\lib\site-packages\telebot\util.py", line 91, in run
    task(*args, **kwargs)
  File "C:\Users\paulo.welton\AppData\Local\Programs\Python\Python39\lib\site-packages\telebot\__init__.py", line 649, in __retrieve_updates
    updates = self.get_updates(offset=(self.last_update_id + 1),
  File "C:\Users\paulo.welton\AppData\Local\Programs\Python\Python39\lib\site-packages\telebot\__init__.py", line 623, in get_updates
    json_updates = apihelper.get_updates(self.token, offset, limit, timeout, allowed_updates, long_polling_timeout)
  File "C:\Users\paulo.welton\AppData\Local\Programs\Python\Python39\lib\site-packages\telebot\apihelper.py", line 321, in get_updates
    return _make_request(token, method_url, params=payload)
  File "C:\Users\paulo.welton\AppData\Local\Programs\Python\Python39\lib\site-packages\telebot\apihelper.py", line 162, in _make_request
    json_result = _check_result(method_name, result)
  File "C:\Users\paulo.welton\AppData\Local\Programs\Python\Python39\lib\site-packages\telebot\apihelper.py", line 189, in _check_result
    raise ApiTelegramException(method_name, result, result_json)
telebot.apihelper.ApiTelegramException: A request to the Telegram API was unsuccessful. Error code: 409. Description: Conflict: can't use getUpdates method while webhook is active; use deleteWebhook to delete the webhook first

 11/04/2025 11:53:04 AM - ERROR - Threaded polling exception: A request to the Telegram API was unsuccessful. Error code: 409. Description: Conflict: can't use getUpdates method while webhook is active; use deleteWebhook to delete the webhook first
 11/04/2025 11:53:04 AM - ERROR - Exception traceback:
Traceback (most recent call last):
  File "C:\Users\paulo.welton\AppData\Local\Programs\Python\Python39\lib\site-packages\telebot\__init__.py", line 1073, in __threaded_polling
    polling_thread.raise_exceptions()
  File "C:\Users\paulo.welton\AppData\Local\Programs\Python\Python39\lib\site-packages\telebot\util.py", line 109, in raise_exceptions
    raise self.exception_info
  File "C:\Users\paulo.welton\AppData\Local\Programs\Python\Python39\lib\site-packages\telebot\util.py", line 91, in run
    task(*args, **kwargs)
  File "C:\Users\paulo.welton\AppData\Local\Programs\Python\Python39\lib\site-packages\telebot\__init__.py", line 649, in __retrieve_updates
    updates = self.get_updates(offset=(self.last_update_id + 1),
  File "C:\Users\paulo.welton\AppData\Local\Programs\Python\Python39\lib\site-packages\telebot\__init__.py", line 623, in get_updates
    json_updates = apihelper.get_updates(self.token, offset, limit, timeout, allowed_updates, long_polling_timeout)
  File "C:\Users\paulo.welton\AppData\Local\Programs\Python\Python39\lib\site-packages\telebot\apihelper.py", line 321, in get_updates
    return _make_request(token, method_url, params=payload)
  File "C:\Users\paulo.welton\AppData\Local\Programs\Python\Python39\lib\site-packages\telebot\apihelper.py", line 162, in _make_request
    json_result = _check_result(method_name, result)
  File "C:\Users\paulo.welton\AppData\Local\Programs\Python\Python39\lib\site-packages\telebot\apihelper.py", line 189, in _check_result
    raise ApiTelegramException(method_name, result, result_json)
telebot.apihelper.ApiTelegramException: A request to the Telegram API was unsuccessful. Error code: 409. Description: Conflict: can't use getUpdates method while webhook is active; use deleteWebhook to delete the webhook first

 11/04/2025 11:55:51 AM - INFO - BOT TELEGRAM YOUTUBE

 11/04/2025 11:55:51 AM - INFO - bot chamado
 11/04/2025 11:56:10 AM - INFO - usuario esta tentando fazer download
 11/04/2025 11:56:12 AM - INFO - ALEE_-_PAG_O_Ft__KLISMAN: https://youtu.be/EfJMGfM3c5Q?si=v_LBRmUKMXrfWB8I
 11/04/2025 11:56:16 AM - INFO - o usuario pediu a opcao video
 11/04/2025 11:56:23 AM - ERROR - Infinity polling exception: 6490586194
 11/04/2025 11:56:23 AM - ERROR - Exception traceback:
Traceback (most recent call last):
  File "C:\Users\paulo.welton\AppData\Local\Programs\Python\Python39\lib\site-packages\telebot\__init__.py", line 955, in infinity_polling
    self.polling(non_stop=True, timeout=timeout, long_polling_timeout=long_polling_timeout,
  File "C:\Users\paulo.welton\AppData\Local\Programs\Python\Python39\lib\site-packages\telebot\__init__.py", line 1043, in polling
    self.__threaded_polling(non_stop=non_stop, interval=interval, timeout=timeout, long_polling_timeout=long_polling_timeout,
  File "C:\Users\paulo.welton\AppData\Local\Programs\Python\Python39\lib\site-packages\telebot\__init__.py", line 1118, in __threaded_polling
    raise e
  File "C:\Users\paulo.welton\AppData\Local\Programs\Python\Python39\lib\site-packages\telebot\__init__.py", line 1074, in __threaded_polling
    self.worker_pool.raise_exceptions()
  File "C:\Users\paulo.welton\AppData\Local\Programs\Python\Python39\lib\site-packages\telebot\util.py", line 148, in raise_exceptions
    raise self.exception_info
  File "C:\Users\paulo.welton\AppData\Local\Programs\Python\Python39\lib\site-packages\telebot\util.py", line 91, in run
    task(*args, **kwargs)
  File "c:\Users\paulo.welton\Desktop\bot_telegram_youtube\src\model\bot.py", line 46, in processar_escolha
    bot.register_next_step_handler(msg, enviar_video_via_email, user_data[chat_id])
KeyError: 6490586194

 11/04/2025 11:58:34 AM - INFO - BOT TELEGRAM YOUTUBE

 11/04/2025 11:58:34 AM - INFO - bot chamado
 11/04/2025 11:59:03 AM - INFO - usuario esta tentando fazer download
 11/04/2025 11:59:04 AM - INFO - ALEE_-_PAG_O_Ft__KLISMAN: https://youtu.be/EfJMGfM3c5Q?si=v_LBRmUKMXrfWB8I
 11/04/2025 11:59:06 AM - INFO - o usuario pediu a opcao video
 11/04/2025 11:59:36 AM - INFO - caminho: C:\Users\paulo.welton\Desktop\bot_telegram_youtube\video\ALEE_-_PAG_O_Ft__KLISMAN.m4a
 11/04/2025 12:07:51 PM - INFO - BOT TELEGRAM YOUTUBE

 11/04/2025 12:07:51 PM - INFO - bot chamado
 11/04/2025 12:08:03 PM - INFO - usuario esta tentando fazer download
 11/04/2025 12:08:04 PM - INFO - ALEE_-_PAG_O_Ft__KLISMAN: https://youtu.be/EfJMGfM3c5Q?si=v_LBRmUKMXrfWB8I
 11/04/2025 12:08:09 PM - INFO - o usuario pediu a opcao video
 11/04/2025 12:08:18 PM - INFO - caminho: C:\Users\paulo.welton\Desktop\bot_telegram_youtube\video\ALEE_-_PAG_O_Ft__KLISMAN.m4a
